Workbook

Sheet Cover
B2: PALANTIR TECHNOLOGIES INC. (NASDAQ: PLTR)
B3: Three-Statement Financial Model · AI & Data Analytics Software
B4: Integrated Income Statement · Balance Sheet · Cash Flow · driver-based forecast · regional scenarios · live market data
B6: AUTHOR & VERSION
B7: Prepared by: Avash Pardhootman
B8: =HYPERLINK("mailto:avash.pardhootman@gmail.com","Contact: avash.pardhootman@gmail.com") -> Contact: avash.pardhootman@gmail.com
B9: =HYPERLINK("https://www.linkedin.com/in/avashpardhootman/","LinkedIn: linkedin.com/in/avashpardhootman") -> LinkedIn: linkedin.com/in/avashpardhootman
B10: Date: July 2026 · Model version: 1.7 (see Version History) · Units: USD thousands, except per-share
B11: Periods: FY2023–FY2025 actual (per SEC filings) · FY2026–FY2030 forecast
B13: QUICK LINKS
B14: =HYPERLINK("Finance_AI_Dashboard.html","▸ Interactive dashboard · toggle industry, scenario and region in your browser (same folder)") -> ▸ Interactive dashboard · toggle industry, scenario and region in your browser (same folder)
B15: =HYPERLINK("README.md","▸ Portfolio README · overview of all three models and how they fit together") -> ▸ Portfolio README · overview of all three models and how they fit together
B16: =HYPERLINK("refresh_market_data.py","▸ Market-data refresh script · run to update prices, rates and refresh stamps everywhere") -> ▸ Market-data refresh script · run to update prices, rates and refresh stamps everywhere
B18: CONTENTS
B19: =HYPERLINK("#'Assumptions'!A1","▸ Assumptions · Margin, tax, working-capital and financing drivers") -> ▸ Assumptions · Margin, tax, working-capital and financing drivers
B20: =HYPERLINK("#'Revenue Drivers'!A1","▸ Revenue Drivers · Bottoms-up sector build driving revenue and key costs") -> ▸ Revenue Drivers · Bottoms-up sector build driving revenue and key costs
B21: =HYPERLINK("#'Regional Breakdown'!A1","▸ Regional Breakdown · NA / Europe / APAC splits and the Standard / Best / Low case selector") -> ▸ Regional Breakdown · NA / Europe / APAC splits and the Standard / Best / Low case selector
B22: =HYPERLINK("#'Income Statement'!A1","▸ Income Statement · Revenue build-down to EPS") -> ▸ Income Statement · Revenue build-down to EPS
B23: =HYPERLINK("#'Balance Sheet'!A1","▸ Balance Sheet · Assets, liabilities and equity, with balance check") -> ▸ Balance Sheet · Assets, liabilities and equity, with balance check
B24: =HYPERLINK("#'Cash Flow'!A1","▸ Cash Flow · Indirect-method cash flow; ending cash links to the balance sheet") -> ▸ Cash Flow · Indirect-method cash flow; ending cash links to the balance sheet
B25: =HYPERLINK("#'Budget vs Actual'!A1","▸ Budget vs Actual · FY2025 vs guidance with automatic >10% variance flagging") -> ▸ Budget vs Actual · FY2025 vs guidance with automatic >10% variance flagging
B26: =HYPERLINK("#'Market Inputs'!A1","▸ Market Inputs · Rates and valuation multiples with refresh stamps") -> ▸ Market Inputs · Rates and valuation multiples with refresh stamps
B27: =HYPERLINK("#'Competitor Benchmarking'!A1","▸ Competitor Benchmarking · Two public comps + peer median + industry benchmarks") -> ▸ Competitor Benchmarking · Two public comps + peer median + industry benchmarks
B28: =HYPERLINK("#'Version History'!A1","▸ Version History · Audit log of every assumptions and data refresh") -> ▸ Version History · Audit log of every assumptions and data refresh
B29: =HYPERLINK("#'Sources'!A1","▸ Sources · Where every input comes from: citations, links, last-updated dates") -> ▸ Sources · Where every input comes from: citations, links, last-updated dates
B31: HOW TO USE THIS MODEL
B32: 1. Start on the Revenue Drivers and Assumptions tabs; every blue cell is an input; yellow cells are the key levers.
B33: 2. Flip the scenario selector on Regional Breakdown (1 = Standard · 2 = Best Case · 3 = Low Case); the whole model re-runs, including EPS, cash and the benchmarking tab.
B34: 3. Check Budget vs Actual for FY2025 performance vs guidance; rows over the 10% threshold flag automatically.
B35: 4. Keep market data current: run refresh_market_data.py in this folder (or use the dashboard ⟳ button); stamps update on Market Inputs and the refresh is logged in Version History.
B36: 5. For a browser walkthrough or a one-page memo, open Finance_AI_Dashboard.html and use Export memo (PDF).
B38: MODEL NOTES
B39: • FY2023–FY2025 as reported in SEC filings; historical statements tie to reported totals. FY2026E revenue growth (60.5%) anchors to management guidance of $7.18–7.20bn.
B40: • Forecast driven entirely by the Revenue Drivers, Assumptions and Regional Breakdown tabs; no hardcodes on statement tabs after FY2025.
B41: • Interest income accrues on beginning-of-year balances (no circular references); balance sheet balances in all periods under every scenario.
B43: COLOR CONVENTIONS
B44: Blue = hardcoded input (historical figures as reported; forecast assumptions)
... B48: Every data input is cited on the Sources tab, with links and last-updated dates.

Sheet Assumptions
A1: Palantir Technologies Inc.; Forecast Assumptions
A2: (USD in thousands, except per-share amounts) · FY2023A–FY2025A per SEC filings · FY2026E–FY2030E forecast
B3: FY2023A | C3: FY2024A | D3: FY2025A | E3: FY2026E | F3: FY2027E | G3: FY2028E | H3: FY2029E | I3: FY2030E
A4: Income statement drivers
A5: Revenue growth % · OUTPUT (driven by Revenue Drivers tab) | C5: ='Income Statement'!C4/'Income Statement'!B4-1 -> 0.28786137 | D5: ='Income Statement'!D4/'Income Statement'!C4-1 -> 0.56183391 | E5: ='Income Statement'!E4/'Income Statement'!D4-1 -> 0.60445227 | F5: ='Income Statement'!F4/'Income Statement'!E4-1 -> 0.43761967 | G5: ='Income Statement'!G4/'Income Statement'!F4-1 -> 0.35579708 | H5: ='Income Statement'!H4/'Income Statement'!G4-1 -> 0.28753739 | I5: ='Income Statement'!I4/'Income Statement'!H4-1 -> 0.23987327 | K5: FY26E ≈ company guidance of $7.18–7.20bn (+61% y/y); growth tapers as base scales
A6: Gross margin % · OUTPUT (driven by Revenue Drivers tab) | B6: ='Income Statement'!B6/'Income Statement'!B4 -> 0.80624599 | C6: ='Income Statement'!C6/'Income Statement'!C4 -> 0.80248172 | D6: ='Income Statement'!D6/'Income Statement'!D4 -> 0.82366517 | E6: ='Income Statement'!E6/'Income Statement'!E4 -> 0.82744198 | F6: ='Income Statement'!F6/'Income Statement'!F4 -> 0.82886622 | G6: ='Income Statement'!G6/'Income Statement'!G4 -> 0.83304674 | H6: ='Income Statement'!H6/'Income Statement'!H4 -> 0.83776048 | I6: ='Income Statement'!I6/'Income Statement'!I4 -> 0.84325836 | K6: Software gross margin with modest AI-compute drag offset by scale
A7: Sales & marketing % of revenue | B7: ='Income Statement'!B9/'Income Statement'!B4 -> 0.33482606 | C7: ='Income Statement'!C9/'Income Statement'!C4 -> 0.3098073 | D7: ='Income Statement'!D9/'Income Statement'!D4 -> 0.23614607 | E7: 0.21 | F7: 0.19 | G7: 0.175 | H7: 0.163 | I7: 0.152 | K7: Operating leverage continues (FY23: 33% → FY25: 24%)
A8: Research & development % of revenue | B8: ='Income Statement'!B10/'Income Statement'!B4 -> 0.1818525 | C8: ='Income Statement'!C10/'Income Statement'!C4 -> 0.17723844 | D8: ='Income Statement'!D10/'Income Statement'!D4 -> 0.12460814 | E8: 0.12 | F8: 0.115 | G8: 0.112 | H8: 0.109 | I8: 0.106
A9: General & administrative % of revenue | B9: ='Income Statement'!B11/'Income Statement'!B4 -> 0.23565041 | C9: ='Income Statement'!C11/'Income Statement'!C4 -> 0.20711204 | D9: ='Income Statement'!D11/'Income Statement'!D4 -> 0.14696144 | E9: 0.125 | F9: 0.112 | G9: 0.102 | H9: 0.095 | I9: 0.089
A10: Stock-based compensation % of revenue | B10: ='Cash Flow'!B7/'Income Statement'!B4 -> 0.21388784 | C10: ='Cash Flow'!C7/'Income Statement'!C4 -> 0.24136671 | D10: ='Cash Flow'!D7/'Income Statement'!D4 -> 0.1528413 | E10: 0.13 | F10: 0.115 | G10: 0.102 | H10: 0.093 | I10: 0.086 | K10: Declines as fixed grant pools amortize over a larger revenue base
A11: Depreciation & amortization % of revenue | B11: ='Cash Flow'!B6/'Income Statement'!B4 -> 0.014990481 | C11: ='Cash Flow'!C6/'Income Statement'!C4 -> 0.01102318 | D11: ='Cash Flow'!D6/'Income Statement'!D4 -> 0.0058418759 | E11: 0.006 | F11: 0.006 | G11: 0.006 | H11: 0.006 | I11: 0.006
A12: Effective tax rate % | B12: ='Income Statement'!B18/'Income Statement'!B17 -> 0.083157944 | C12: ='Income Statement'!C18/'Income Statement'!C17 -> 0.043450885 | D12: ='Income Statement'!D18/'Income Statement'!D17 -> 0.013710896 | E12: 0.05 | F12: 0.12 | G12: 0.18 | H12: 0.21 | I12: 0.23 | K12: Steps toward statutory rate as NOL/valuation-allowance benefits are consumed
A13: Interest yield on beginning cash & investments % | C13: ='Income Statement'!C15/('Balance Sheet'!B5+'Balance Sheet'!B6) -> 0.053560809 | D13: ='Income Statement'!D15/('Balance Sheet'!C5+'Balance Sheet'!C6) -> 0.043820568 | E13: 0.04 | F13: 0.04 | G13: 0.04 | H13: 0.04 | I13: 0.04 | K13: Applied to beginning-of-year cash + marketable securities (avoids circularity)
A14: Diluted share count growth % | C14: ='Income Statement'!C23/'Income Statement'!B23-1 -> 0.066534315 | D14: ='Income Statement'!D23/'Income Statement'!C23-1 -> 0.046669724 | E14: 0.015 | F14: 0.014 | G14: 0.013 | H14: 0.012 | I14: 0.011
A16: Balance sheet drivers
A17: Accounts receivable · days sales outstanding | B17: ='Balance Sheet'!B7/'Income Statement'!B4*365 -> 59.840648 | C17: ='Balance Sheet'!C7/'Income Statement'!C4*365 -> 73.247952 | D17: ='Balance Sheet'!D7/'Income Statement'!D4*365 -> 84.986776 | E17: 85 | F17: 84 | G17: 83 | H17: 82 | I17: 81 | K17: Large government/strategic contracts lengthen collections
A18: Prepaid & other current assets % of revenue | B18: ='Balance Sheet'!B8/'Income Statement'!B4 -> 0.044788522 | C18: ='Balance Sheet'!C8/'Income Statement'!C4 -> 0.045106852 | D18: ='Balance Sheet'!D8/'Income Statement'!D4 -> 0.031073104 | E18: 0.031 | F18: 0.031 | G18: 0.031 | H18: 0.031 | I18: 0.031
A19: Other assets % of revenue | B19: ='Balance Sheet'!B12/'Income Statement'!B4 -> 0.068847269 | C19: ='Balance Sheet'!C12/'Income Statement'!C4 -> 0.05800614 | D19: ='Balance Sheet'!D12/'Income Statement'!D4 -> 0.064832198 | E19: 0.065 | F19: 0.065 | G19: 0.065 | H19: 0.065 | I19: 0.065
A20: Accounts payable % of total costs | B20: ='Balance Sheet'!B16/('Income Statement'!B5+'Income Statement'!B12) -> 0.005758544 | C20: ='Balance Sheet'!C16/('Income Statement'!C5+'Income Statement'!C12) -> 4.0311471e-05 | D20: ='Balance Sheet'!D16/('Income Statement'!D5+'Income Statement'!D12) -> 0.0026340623 | E20: 0.003 | F20: 0.003 | G20: 0.003 | H20: 0.003 | I20: 0.003
A21: Accrued liabilities % of total costs | B21: ='Balance Sheet'!B17/('Income Statement'!B5+'Income Statement'!B12) -> 0.10593165 | C21: ='Balance Sheet'!C17/('Income Statement'!C5+'Income Statement'!C12) -> 0.16713449 | D21: ='Balance Sheet'!D17/('Income Statement'!D5+'Income Statement'!D12) -> 0.11616267 | E21: 0.115 | F21: 0.113 | G21: 0.111 | H21: 0.109 | I21: 0.107
A22: Deferred revenue (current) % of revenue | B22: ='Balance Sheet'!B18/'Income Statement'!B4 -> 0.11096614 | C22: ='Balance Sheet'!C18/'Income Statement'!C4 -> 0.090603164 | D22: ='Balance Sheet'!D18/'Income Statement'!D4 -> 0.091379273 | E22: 0.091 | F22: 0.091 | G22: 0.091 | H22: 0.091 | I22: 0.091
A23: Deferred revenue (noncurrent) % of revenue | B23: ='Balance Sheet'!B22/'Income Statement'!B4 -> 0.012605325 | C23: ='Balance Sheet'!C22/'Income Statement'!C4 -> 0.013919003 | D23: ='Balance Sheet'!D22/'Income Statement'!D4 -> 0.010326569 | E23: 0.01 | F23: 0.01 | G23: 0.01 | H23: 0.01 | I23: 0.01
A24: Customer deposits (current) % of revenue | B24: ='Balance Sheet'!B19/'Income Statement'!B4 -> 0.09430421 | C24: ='Balance Sheet'!C19/'Income Statement'!C4 -> 0.092567214 | D24: ='Balance Sheet'!D19/'Income Statement'!D4 -> 0.079783333 | E24: 0.079 | F24: 0.078 | G24: 0.077 | H24: 0.076 | I24: 0.075
A25: Capital expenditures % of revenue | B25: =-1*'Cash Flow'!B17/'Income Statement'!B4 -> 0.0067927724 | C25: =-1*'Cash Flow'!C17/'Income Statement'!C4 -> 0.0044089929 | D25: =-1*'Cash Flow'!D17/'Income Statement'!D4 -> 0.0075706421 | E25: 0.01 | F25: 0.01 | G25: 0.009 | H25: 0.009 | I25: 0.008
A27: Financing drivers ($000s)
A28: Share repurchases | B28: =-'Cash Flow'!B24 -> 0 | C28: =-'Cash Flow'!C24 -> 64196 | D28: =-'Cash Flow'!D24 -> 74985 | E28: 300000 | F28: 400000 | G28: 500000 | H28: 600000 | I28: 700000 | K28: Discretionary; scales with free cash flow
A29: Proceeds from option exercises | B29: ='Cash Flow'!B23 -> 218238 | C29: ='Cash Flow'!C23 -> 745396 | D29: ='Cash Flow'!D23 -> 129107 | E29: 150000 | F29: 150000 | G29: 150000 | H29: 150000 | I29: 150000
A30: Taxes paid on net share settlement | B30: =-'Cash Flow'!B25 -> 0 | C30: =-'Cash Flow'!C25 -> 218280 | D30: =-'Cash Flow'!D25 -> 81117 | E30: 100000 | F30: 100000 | G30: 100000 | H30: 100000 | I30: 100000
A32: Historical columns compute actual ratios from the statement tabs; forecast columns (blue) are inputs.
A33: Marketable securities, lease balances and noncontrolling interests held flat in the forecast for simplicity.

Sheet Revenue Drivers
A1: Palantir Technologies Inc.; Revenue Drivers (AI)
A2: Bottoms-up AI revenue & compute-cost build (USD in thousands unless noted) · drives Revenue and Cost of revenue on the Income Statement
B3: FY2023A | C3: FY2024A | D3: FY2025A | E3: FY2026E | F3: FY2027E | G3: FY2028E | H3: FY2029E | I3: FY2030E
A4: Government segment
A5: Government revenue ($000s) | B5: 1222200 | C5: 1569600 | D5: 2402000 | E5: =D5*(1+E6) -> 3651040 | F5: =E5*(1+F6) -> 4965414.4 | G5: =F5*(1+G6) -> 6355730.4 | H5: =G5*(1+H6) -> 7753991.1 | I5: =H5*(1+I6) -> 9149709.5
A6: Government revenue growth % | C6: =C5/B5-1 -> 0.28424153 | D6: =D5/C5-1 -> 0.5303262 | E6: 0.52 | F6: 0.36 | G6: 0.28 | H6: 0.22 | I6: 0.18
A8: Commercial segment · enterprise contracts
A9: Commercial customers (end of period) | B9: 375 | C9: 571 | D9: 780 | E9: =D9*(1+E10) -> 1029.6 | F9: =E9*(1+F10) -> 1307.592 | G9: =F9*(1+G10) -> 1608.3382 | H9: =G9*(1+H10) -> 1913.9224 | I9: =H9*(1+I10) -> 2220.15
A10: Commercial customer growth % | C10: =C9/B9-1 -> 0.52266667 | D10: =D9/C9-1 -> 0.36602452 | E10: 0.32 | F10: 0.27 | G10: 0.23 | H10: 0.19 | I10: 0.16
A11: Average enterprise contract value ($000s / customer / yr) | B11: =B13/B9 -> 2674.1653 | C11: =C13/C9 -> 2269.5394 | D11: =D13/D9 -> 2658.2641 | E11: =D11*(1+E12) -> 3136.7516 | F11: =E11*(1+F12) -> 3575.8969 | G11: =F11*(1+G12) -> 4005.0045 | H11: =G11*(1+H12) -> 4405.5049 | I11: =H11*(1+I12) -> 4802.0004
A12: Enterprise contract value growth % | C12: =C11/B11-1 -> -0.15130924 | D12: =D11/C11-1 -> 0.17127911 | E12: 0.18 | F12: 0.14 | G12: 0.12 | H12: 0.1 | I12: 0.09
A13: Commercial enterprise revenue ($000s) | B13: 1002812 | C13: 1295907 | D13: 2073446 | E13: =E9*E11 -> 3229599.5 | F13: =F9*F11 -> 4675814.1 | G13: =G9*G11 -> 6441401.6 | H13: =H9*H11 -> 8431794.6 | I13: =I9*I11 -> 10661161
A15: AIP subscription tiers (illustrative self-serve ramp from FY2026E)
A16: Starter tier · customers | E16: 4000 | F16: 9000 | G16: 16000 | H16: 25000 | I16: 35000
A17: Starter tier · annual price ($000s) | E17: 15 | F17: 15.5 | G17: 16 | H17: 16.5 | I17: 17
A18: Professional tier · customers | E18: 1500 | F18: 3400 | G18: 6200 | H18: 9500 | I18: 13000
A19: Professional tier · annual price ($000s) | E19: 60 | F19: 62 | G19: 64 | H19: 66 | I19: 68
A20: Enterprise AIP tier · customers | E20: 300 | F20: 650 | G20: 1050 | H20: 1500 | I20: 1950
A21: Enterprise AIP tier · annual price ($000s) | E21: 500 | F21: 510 | G21: 520 | H21: 530 | I21: 540
A22: Subscription tier revenue ($000s) | E22: =E16*E17+E18*E19+E20*E21 -> 300000 | F22: =F16*F17+F18*F19+F20*F21 -> 681800 | G22: =G16*G17+G18*G19+G20*G21 -> 1198800 | H22: =H16*H17+H18*H19+H20*H21 -> 1834500 | I22: =I16*I17+I18*I19+I20*I21 -> 2532000
A24: TOTAL REVENUE ($000s) | B24: =SUM(B5,B13,B22) -> 2225012 | C24: =SUM(C5,C13,C22) -> 2865507 | D24: =SUM(D5,D13,D22) -> 4475446 | E24: =SUM(E5,E13,E22) -> 7180639.5 | F24: =SUM(F5,F13,F22) -> 10323029 | G24: =SUM(G5,G13,G22) -> 13995932 | H24: =SUM(H5,H13,H22) -> 18020286 | I24: =SUM(I5,I13,I22) -> 22342871
A25: Total revenue growth % | C25: =C24/B24-1 -> 0.28786137 | D25: =D24/C24-1 -> 0.56183391 | E25: =E24/D24-1 -> 0.60445227 | F25: =F24/E24-1 -> 0.43761967 | G25: =G24/F24-1 -> 0.35579708 | H25: =H24/G24-1 -> 0.28753739 | I25: =I24/H24-1 -> 0.23987327
A26: Check vs Regional Breakdown base (must be 0) | B26: =B24-'Regional Breakdown'!B18 -> 0 | C26: =C24-'Regional Breakdown'!C18 -> 0 | D26: =D24-'Regional Breakdown'!D18 -> 0 | E26: =E24-'Regional Breakdown'!E18 -> 0 | F26: =F24-'Regional Breakdown'!F18 -> 0 | G26: =G24-'Regional Breakdown'!G18 -> 0 | H26: =H24-'Regional Breakdown'!H18 -> 0 | I26: =I24-'Regional Breakdown'!I18 -> 0
A28: AI compute economics (drives cost of revenue)
A29: AI queries / inference calls processed (billions) | E29: 1500 | F29: 2600 | G29: 4100 | H29: 6000 | I29: 8200
A30: Compute cost per query ($) | E30: 0.0004 | F30: 0.00034 | G30: 0.00029 | H30: 0.00025 | I30: 0.00022
A31: Total compute cost ($000s) | E31: =E29*E30*1000000 -> 600000 | F31: =F29*F30*1000000 -> 884000 | G31: =G29*G30*1000000 -> 1189000 | H31: =H29*H30*1000000 -> 1500000 | I31: =I29*I30*1000000 -> 1804000
A32: Other cost of revenue % of total revenue | E32: 0.089 | F32: 0.0855 | G32: 0.082 | H32: 0.079 | I32: 0.076
A33: Other cost of revenue ($000s) | E33: ='Income Statement'!E4*E32 -> 639076.91 | F33: ='Income Statement'!F4*F32 -> 882618.94 | G33: ='Income Statement'!G4*G32 -> 1147666.4 | H33: ='Income Statement'!H4*H32 -> 1423602.6 | I33: ='Income Statement'!I4*I32 -> 1698058.2
A34: TOTAL COST OF REVENUE ($000s) | B34: ='Income Statement'!B5 -> 431105 | C34: ='Income Statement'!C5 -> 565990 | D34: ='Income Statement'!D5 -> 789177 | E34: =E31+E33 -> 1239076.9 | F34: =F31+F33 -> 1766618.9 | G34: =G31+G33 -> 2336666.4 | H34: =H31+H33 -> 2923602.6 | I34: =I31+I33 -> 3502058.2
A35: Implied gross margin % | B35: =1-B34/B24 -> 0.80624599 | C35: =1-C34/C24 -> 0.80248172 | D35: =1-D34/D24 -> 0.82366517 | E35: =1-E34/'Income Statement'!E4 -> 0.82744198 | F35: =1-F34/'Income Statement'!F4 -> 0.82886622 | G35: =1-G34/'Income Statement'!G4 -> 0.83304674 | H35: =1-H34/'Income Statement'!H4 -> 0.83776048 | I35: =1-I34/'Income Statement'!I4 -> 0.84325836
A37: Government / commercial splits and customer counts per company disclosures (10-Ks, Q4 FY2025 investor presentation).
A38: Palantir does not disclose query volumes or unit compute costs; the compute block is an illustrative unit-economics frame (inputs in blue).
A39: Subscription tiers model an illustrative AIP self-serve ramp; set tier customer counts to zero to remove.

Sheet Regional Breakdown
A1: Palantir Technologies Inc.; Regional Breakdown & Scenarios
A2: Revenue, growth and customers by region (USD in thousands unless noted) · regional scenario toggle feeds the Income Statement · base = total revenue
B3: FY2023A | C3: FY2024A | D3: FY2025A | E3: FY2026E | F3: FY2027E | G3: FY2028E | H3: FY2029E | I3: FY2030E
A4: SCENARIO SELECTOR (1 = Standard · 2 = Best Case · 3 = Low Case) | B4: 1 | C4: =CHOOSE(B4,"STANDARD CASE","BEST CASE","LOW CASE") -> STANDARD CASE
A6: REGIONAL MIX (% of total revenue)
A7: North America mix % | B7: 0.619 | C7: 0.663 | D7: 0.742 | E7: 0.73 | F7: 0.72 | G7: 0.71 | H7: 0.7 | I7: 0.69
A8: Europe mix % | B8: 0.27 | C8: 0.235 | D8: 0.18 | E8: 0.185 | F8: 0.19 | G8: 0.195 | H8: 0.2 | I8: 0.205
A9: Asia Pacific mix % | B9: 0.07 | C9: 0.065 | D9: 0.05 | E9: 0.055 | F9: 0.06 | G9: 0.065 | H9: 0.07 | I9: 0.075
A10: Other / rest of world mix % (balancing) | B10: =1-B7-B8-B9 -> 0.041 | C10: =1-C7-C8-C9 -> 0.037 | D10: =1-D7-D8-D9 -> 0.028 | E10: =1-E7-E8-E9 -> 0.03 | F10: =1-F7-F8-F9 -> 0.03 | G10: =1-G7-G8-G9 -> 0.03 | H10: =1-H7-H8-H9 -> 0.03 | I10: =1-I7-I8-I9 -> 0.03
A12: BASE TOTAL REVENUE BY REGION ($000s)
A13: Base total revenue before regional split | B13: ='Revenue Drivers'!B24 -> 2225012 | C13: ='Revenue Drivers'!C24 -> 2865507 | D13: ='Revenue Drivers'!D24 -> 4475446 | E13: ='Revenue Drivers'!E24 -> 7180639.5 | F13: ='Revenue Drivers'!F24 -> 10323029 | G13: ='Revenue Drivers'!G24 -> 13995932 | H13: ='Revenue Drivers'!H24 -> 18020286 | I13: ='Revenue Drivers'!I24 -> 22342871
A14: North America · base | B14: =B13*B7 -> 1377282.4 | C14: =C13*C7 -> 1899831.1 | D14: =D13*D7 -> 3320780.9 | E14: =E13*E7 -> 5241866.8 | F14: =F13*F7 -> 7432580.5 | G14: =G13*G7 -> 9937111.7 | H14: =H13*H7 -> 12614200 | I14: =I13*I7 -> 15416581
A15: Europe · base | B15: =B13*B8 -> 600753.24 | C15: =C13*C8 -> 673394.15 | D15: =D13*D8 -> 805580.28 | E15: =E13*E8 -> 1328418.3 | F15: =F13*F8 -> 1961375.4 | G15: =G13*G8 -> 2729206.7 | H15: =H13*H8 -> 3604057.2 | I15: =I13*I8 -> 4580288.5
A16: Asia Pacific · base | B16: =B13*B9 -> 155750.84 | C16: =C13*C9 -> 186257.95 | D16: =D13*D9 -> 223772.3 | E16: =E13*E9 -> 394935.17 | F16: =F13*F9 -> 619381.71 | G16: =G13*G9 -> 909735.58 | H16: =H13*H9 -> 1261420 | I16: =I13*I9 -> 1675715.3
A17: Other / rest of world · base | B17: =B13*B10 -> 91225.492 | C17: =C13*C10 -> 106023.76 | D17: =D13*D10 -> 125312.49 | E17: =E13*E10 -> 215419.18 | F17: =F13*F10 -> 309690.86 | G17: =G13*G10 -> 419877.96 | H17: =H13*H10 -> 540608.57 | I17: =I13*I10 -> 670286.12
A18: Total base (sum of regions) | B18: =SUM(B14:B17) -> 2225012 | C18: =SUM(C14:C17) -> 2865507 | D18: =SUM(D14:D17) -> 4475446 | E18: =SUM(E14:E17) -> 7180639.5 | F18: =SUM(F14:F17) -> 10323029 | G18: =SUM(G14:G17) -> 13995932 | H18: =SUM(H14:H17) -> 18020286 | I18: =SUM(I14:I17) -> 22342871
A20: BASE REGIONAL GROWTH %
A21: North America growth % | C21: =C14/B14-1 -> 0.37940563 | D21: =D14/C14-1 -> 0.74793478 | E21: =E14/D14-1 -> 0.57850425 | F21: =F14/E14-1 -> 0.41792625 | G21: =G14/F14-1 -> 0.33696657 | H21: =H14/G14-1 -> 0.26940306 | I21: =I14/H14-1 -> 0.2221608
A22: Europe growth % | C22: =C15/B15-1 -> 0.12091638 | D22: =D15/C15-1 -> 0.19629831 | E22: =E15/D15-1 -> 0.64902039 | F22: =F15/E15-1 -> 0.47647425 | G22: =G15/F15-1 -> 0.39147595 | H22: =H15/G15-1 -> 0.32055117 | I22: =I15/H15-1 -> 0.2708701
A23: Asia Pacific growth % | C23: =C16/B16-1 -> 0.19587127 | D23: =D16/C16-1 -> 0.2014107 | E23: =E16/D16-1 -> 0.7648975 | F23: =F16/E16-1 -> 0.56831236 | G23: =G16/F16-1 -> 0.46878017 | H23: =H16/G16-1 -> 0.38657873 | I23: =I16/H16-1 -> 0.32843565
A25: SCENARIO GROWTH DELTAS (added to base regional growth)
A26: Best Case · North America | E26: 0.02 | F26: 0.02 | G26: 0.02 | H26: 0.02 | I26: 0.02
A27: Best Case · Europe | E27: 0.06 | F27: 0.06 | G27: 0.06 | H27: 0.06 | I27: 0.06
A28: Best Case · Asia Pacific | E28: 0.1 | F28: 0.1 | G28: 0.1 | H28: 0.1 | I28: 0.1
A29: Low Case · North America | E29: -0.04 | F29: -0.04 | G29: -0.04 | H29: -0.04 | I29: -0.04
A30: Low Case · Europe | E30: -0.07 | F30: -0.07 | G30: -0.07 | H30: -0.07 | I30: -0.07
A31: Low Case · Asia Pacific | E31: -0.1 | F31: -0.1 | G31: -0.1 | H31: -0.1 | I31: -0.1
A33: SCENARIO TOTAL REVENUE BY REGION ($000s)
A34: North America · scenario | B34: =B14 -> 1377282.4 | C34: =C14 -> 1899831.1 | D34: =D14 -> 3320780.9 | E34: =D34*(1+E21+CHOOSE($B$4,0,E26,E29)) -> 5241866.8 | F34: =E34*(1+F21+CHOOSE($B$4,0,F26,F29)) -> 7432580.5 | G34: =F34*(1+G21+CHOOSE($B$4,0,G26,G29)) -> 9937111.7 | H34: =G34*(1+H21+CHOOSE($B$4,0,H26,H29)) -> 12614200 | I34: =H34*(1+I21+CHOOSE($B$4,0,I26,I29)) -> 15416581
A35: Europe · scenario | B35: =B15 -> 600753.24 | C35: =C15 -> 673394.15 | D35: =D15 -> 805580.28 | E35: =D35*(1+E22+CHOOSE($B$4,0,E27,E30)) -> 1328418.3 | F35: =E35*(1+F22+CHOOSE($B$4,0,F27,F30)) -> 1961375.4 | G35: =F35*(1+G22+CHOOSE($B$4,0,G27,G30)) -> 2729206.7 | H35: =G35*(1+H22+CHOOSE($B$4,0,H27,H30)) -> 3604057.2 | I35: =H35*(1+I22+CHOOSE($B$4,0,I27,I30)) -> 4580288.5
A36: Asia Pacific · scenario | B36: =B16 -> 155750.84 | C36: =C16 -> 186257.95 | D36: =D16 -> 223772.3 | E36: =D36*(1+E23+CHOOSE($B$4,0,E28,E31)) -> 394935.17 | F36: =E36*(1+F23+CHOOSE($B$4,0,F28,F31)) -> 619381.71 | G36: =F36*(1+G23+CHOOSE($B$4,0,G28,G31)) -> 909735.58 | H36: =G36*(1+H23+CHOOSE($B$4,0,H28,H31)) -> 1261420 | I36: =H36*(1+I23+CHOOSE($B$4,0,I28,I31)) -> 1675715.3
A37: Other / rest of world · scenario (no delta) | B37: =B17 -> 91225.492 | C37: =C17 -> 106023.76 | D37: =D17 -> 125312.49 | E37: =E17 -> 215419.18 | F37: =F17 -> 309690.86 | G37: =G17 -> 419877.96 | H37: =H17 -> 540608.57 | I37: =I17 -> 670286.12
A38: TOTAL · SCENARIO ($000s) | B38: =SUM(B34:B37) -> 2225012 | C38: =SUM(C34:C37) -> 2865507 | D38: =SUM(D34:D37) -> 4475446 | E38: =SUM(E34:E37) -> 7180639.5 | F38: =SUM(F34:F37) -> 10323029 | G38: =SUM(G34:G37) -> 13995932 | H38: =SUM(H34:H37) -> 18020286 | I38: =SUM(I34:I37) -> 22342871
A39: Scenario total growth % | C39: =C38/B38-1 -> 0.28786137 | D39: =D38/C38-1 -> 0.56183391 | E39: =E38/D38-1 -> 0.60445227 | F39: =F38/E38-1 -> 0.43761967 | G39: =G38/F38-1 -> 0.35579708 | H39: =H38/G38-1 -> 0.28753739 | I39: =I38/H38-1 -> 0.23987327
A40: Scenario scaling factor (× base) | B40: =B38/B18 -> 1 | C40: =C38/C18 -> 1 | D40: =D38/D18 -> 1 | E40: =E38/E18 -> 1 | F40: =F38/F18 -> 1 | G40: =G38/G18 -> 1 | H40: =H38/H18 -> 1 | I40: =I38/I18 -> 1
A41: Scenario revenue delta vs base ($000s) | B41: =B38-B18 -> 0 | C41: =C38-C18 -> 0 | D41: =D38-D18 -> 0 | E41: =E38-E18 -> 0 | F41: =F38-F18 -> 0 | G41: =G38-G18 -> 0 | H41: =H38-H18 -> 0 | I41: =I38-I18 -> 0
A43: SCENARIO IMPACT DASHBOARD (flips with the selector)
A44: Net income · scenario ($000s) | B44: ='Income Statement'!B21 -> 209825 | C44: ='Income Statement'!C21 -> 462190 | D44: ='Income Statement'!D21 -> 1625033 | E44: ='Income Statement'!E21 -> 2813380.7 | F44: ='Income Statement'!F21 -> 4107696.1 | G44: ='Income Statement'!G21 -> 5589141.7 | H44: ='Income Statement'!H21 -> 7372338.7 | I44: ='Income Statement'!I21 -> 9439839.6
A45: Diluted EPS · scenario ($) | B45: ='Income Statement'!B24 -> 0.091310559 | C45: ='Income Statement'!C24 -> 0.18858601 | D45: ='Income Statement'!D24 -> 0.63349248 | E45: ='Income Statement'!E24 -> 1.0805422 | F45: ='Income Statement'!F24 -> 1.555871 | G45: ='Income Statement'!G24 -> 2.08983 | H45: ='Income Statement'!H24 -> 2.7238965 | I45: ='Income Statement'!I24 -> 3.4498386
A46: Ending cash · scenario ($000s) | B46: ='Balance Sheet'!B5 -> 831047 | C46: ='Balance Sheet'!C5 -> 2098524 | D46: ='Balance Sheet'!D5 -> 1423796 | E46: ='Balance Sheet'!E5 -> 4649997.8 | F46: ='Balance Sheet'!F5 -> 9276214.5 | G46: ='Balance Sheet'!G5 -> 15467653 | H46: ='Balance Sheet'!H5 -> 23539143 | I46: ='Balance Sheet'!I5 -> 33793587
...

Sheet Income Statement
A1: Palantir Technologies Inc.; Income Statement
A2: (USD in thousands, except per-share amounts) · FY2023A–FY2025A per SEC filings · FY2026E–FY2030E forecast
B3: FY2023A | C3: FY2024A | D3: FY2025A | E3: FY2026E | F3: FY2027E | G3: FY2028E | H3: FY2029E | I3: FY2030E
A4: Revenue | B4: 2225012 | C4: 2865507 | D4: 4475446 | E4: ='Regional Breakdown'!E38 -> 7180639.5 | F4: ='Regional Breakdown'!F38 -> 10323029 | G4: ='Regional Breakdown'!G38 -> 13995932 | H4: ='Regional Breakdown'!H38 -> 18020286 | I4: ='Regional Breakdown'!I38 -> 22342871 | K4: Source: PLTR Q4 FY2025 and Q4 FY2024 earnings releases (SEC 8-K Ex. 99.1)
A5: Cost of revenue | B5: 431105 | C5: 565990 | D5: 789177 | E5: ='Revenue Drivers'!E34 -> 1239076.9 | F5: ='Revenue Drivers'!F34 -> 1766618.9 | G5: ='Revenue Drivers'!G34 -> 2336666.4 | H5: ='Revenue Drivers'!H34 -> 2923602.6 | I5: ='Revenue Drivers'!I34 -> 3502058.2
A6: Gross profit | B6: =B4-B5 -> 1793907 | C6: =C4-C5 -> 2299517 | D6: =D4-D5 -> 3686269 | E6: =E4-E5 -> 5941562.6 | F6: =F4-F5 -> 8556409.6 | G6: =G4-G5 -> 11659266 | H6: =H4-H5 -> 15096683 | I6: =I4-I5 -> 18840813
A8: Operating expenses
A9: Sales and marketing | B9: 744992 | C9: 887755 | D9: 1056859 | E9: =E4*Assumptions!E7 -> 1507934.3 | F9: =F4*Assumptions!F7 -> 1961375.4 | G9: =G4*Assumptions!G7 -> 2449288.1 | H9: =H4*Assumptions!H7 -> 2937306.6 | I9: =I4*Assumptions!I7 -> 3396116.3
A10: Research and development | B10: 404624 | C10: 507878 | D10: 557677 | E10: =E4*Assumptions!E8 -> 861676.74 | F10: =F4*Assumptions!F8 -> 1187148.3 | G10: =G4*Assumptions!G8 -> 1567544.4 | H10: =H4*Assumptions!H8 -> 1964211.1 | I10: =I4*Assumptions!I8 -> 2368344.3
A11: General and administrative | B11: 524325 | C11: 593481 | D11: 657718 | E11: =E4*Assumptions!E9 -> 897579.94 | F11: =F4*Assumptions!F9 -> 1156179.2 | G11: =G4*Assumptions!G9 -> 1427585.1 | H11: =H4*Assumptions!H9 -> 1711927.1 | I11: =I4*Assumptions!I9 -> 1988515.5
A12: Total operating expenses | B12: =SUM(B9:B11) -> 1673941 | C12: =SUM(C9:C11) -> 1989114 | D12: =SUM(D9:D11) -> 2272254 | E12: =SUM(E9:E11) -> 3267191 | F12: =SUM(F9:F11) -> 4304702.9 | G12: =SUM(G9:G11) -> 5444417.5 | H12: =SUM(H9:H11) -> 6613444.9 | I12: =SUM(I9:I11) -> 7752976.1
A13: Income from operations | B13: =B6-B12 -> 119966 | C13: =C6-C12 -> 310403 | D13: =D6-D12 -> 1414015 | E13: =E6-E12 -> 2674371.6 | F13: =F6-F12 -> 4251706.7 | G13: =G6-G12 -> 6214848 | H13: =H6-H12 -> 8483238.3 | I13: =I6-I12 -> 11087836
A15: Interest income | B15: 132572 | C15: 196792 | D15: 229181 | E15: =('Balance Sheet'!D5+'Balance Sheet'!D6)*Assumptions!E13 -> 287081.72 | F15: =('Balance Sheet'!E5+'Balance Sheet'!E6)*Assumptions!F13 -> 416129.79 | G15: =('Balance Sheet'!F5+'Balance Sheet'!F6)*Assumptions!G13 -> 601178.46 | H15: =('Balance Sheet'!G5+'Balance Sheet'!G6)*Assumptions!H13 -> 848836 | I15: =('Balance Sheet'!H5+'Balance Sheet'!H6)*Assumptions!I13 -> 1171695.6
A16: Other income (expense), net | B16: -15447 | C16: -18022 | D16: 14172 | E16: 0 | F16: 0 | G16: 0 | H16: 0 | I16: 0
A17: Income before provision for income taxes | B17: =B13+B15+B16 -> 237091 | C17: =C13+C15+C16 -> 489173 | D17: =D13+D15+D16 -> 1657368 | E17: =E13+E15+E16 -> 2961453.3 | F17: =F13+F15+F16 -> 4667836.5 | G17: =G13+G15+G16 -> 6816026.5 | H17: =H13+H15+H16 -> 9332074.3 | I17: =I13+I15+I16 -> 12259532
A18: Provision for income taxes | B18: 19716 | C18: 21255 | D18: 22724 | E18: =E17*Assumptions!E12 -> 148072.67 | F18: =F17*Assumptions!F12 -> 560140.38 | G18: =G17*Assumptions!G12 -> 1226884.8 | H18: =H17*Assumptions!H12 -> 1959735.6 | I18: =I17*Assumptions!I12 -> 2819692.4
A19: Net income | B19: =B17-B18 -> 217375 | C19: =C17-C18 -> 467918 | D19: =D17-D18 -> 1634644 | E19: =E17-E18 -> 2813380.7 | F19: =F17-F18 -> 4107696.1 | G19: =G17-G18 -> 5589141.7 | H19: =H17-H18 -> 7372338.7 | I19: =I17-I18 -> 9439839.6
A20: Less: net income attributable to noncontrolling interests | B20: 7550 | C20: 5728 | D20: 9611 | E20: 0 | F20: 0 | G20: 0 | H20: 0 | I20: 0
A21: Net income attributable to common stockholders | B21: =B19-B20 -> 209825 | C21: =C19-C20 -> 462190 | D21: =D19-D20 -> 1625033 | E21: =E19-E20 -> 2813380.7 | F21: =F19-F20 -> 4107696.1 | G21: =G19-G20 -> 5589141.7 | H21: =H19-H20 -> 7372338.7 | I21: =I19-I20 -> 9439839.6
A23: Weighted-average diluted shares outstanding | B23: 2297927 | C23: 2450818 | D23: 2565197 | E23: =D23*(1+Assumptions!E14) -> 2603675 | F23: =E23*(1+Assumptions!F14) -> 2640126.4 | G23: =F23*(1+Assumptions!G14) -> 2674448 | H23: =G23*(1+Assumptions!H14) -> 2706541.4 | I23: =H23*(1+Assumptions!I14) -> 2736313.4
A24: Diluted EPS ($) | B24: =B21/B23 -> 0.091310559 | C24: =C21/C23 -> 0.18858601 | D24: =D21/D23 -> 0.63349248 | E24: =E21/E23 -> 1.0805422 | F24: =F21/F23 -> 1.555871 | G24: =G21/G23 -> 2.08983 | H24: =H21/H23 -> 2.7238965 | I24: =I21/I23 -> 3.4498386
A26: Memo: stock-based compensation expense | B26: 475903 | C26: 691638 | D26: 684033 | E26: =E4*Assumptions!E10 -> 933483.13 | F26: =F4*Assumptions!F10 -> 1187148.3 | G26: =G4*Assumptions!G10 -> 1427585.1 | H26: =H4*Assumptions!H10 -> 1675886.6 | I26: =I4*Assumptions!I10 -> 1921486.9
A27: Memo: depreciation and amortization | B27: 33354 | C27: 31587 | D27: 26145 | E27: =E4*Assumptions!E11 -> 43083.837 | F27: =F4*Assumptions!F11 -> 61938.171 | G27: =G4*Assumptions!G11 -> 83975.592 | H27: =H4*Assumptions!H11 -> 108121.71 | I27: =I4*Assumptions!I11 -> 134057.22

Sheet Balance Sheet
A1: Palantir Technologies Inc.; Balance Sheet
A2: (USD in thousands, except per-share amounts) · FY2023A–FY2025A per SEC filings · FY2026E–FY2030E forecast
B3: FY2023A | C3: FY2024A | D3: FY2025A | E3: FY2026E | F3: FY2027E | G3: FY2028E | H3: FY2029E | I3: FY2030E
A4: Assets
A5: Cash and cash equivalents | B5: 831047 | C5: 2098524 | D5: 1423796 | E5: ='Cash Flow'!E34 -> 4649997.8 | F5: ='Cash Flow'!F34 -> 9276214.5 | G5: ='Cash Flow'!G34 -> 15467653 | H5: ='Cash Flow'!H34 -> 23539143 | I5: ='Cash Flow'!I34 -> 33793587
A6: Marketable securities | B6: 2843132 | C6: 3131463 | D6: 5753247 | E6: =D6 -> 5753247 | F6: =E6 -> 5753247 | G6: =F6 -> 5753247 | H6: =G6 -> 5753247 | I6: =H6 -> 5753247 | K6: Held flat in forecast; excess cash accumulates in cash & equivalents
A7: Accounts receivable, net | B7: 364784 | C7: 575048 | D7: 1042065 | E7: ='Income Statement'!E4*Assumptions!E17/365 -> 1672203.7 | F7: ='Income Statement'!F4*Assumptions!F17/365 -> 2375710.7 | G7: ='Income Statement'!G4*Assumptions!G17/365 -> 3182636.6 | H7: ='Income Statement'!H4*Assumptions!H17/365 -> 4048393 | I7: ='Income Statement'!I4*Assumptions!I17/365 -> 4958280.9
A8: Prepaid expenses and other current assets | B8: 99655 | C8: 129254 | D8: 139066 | E8: ='Income Statement'!E4*Assumptions!E18 -> 222599.82 | F8: ='Income Statement'!F4*Assumptions!F18 -> 320013.88 | G8: ='Income Statement'!G4*Assumptions!G18 -> 433873.89 | H8: ='Income Statement'!H4*Assumptions!H18 -> 558628.86 | I8: ='Income Statement'!I4*Assumptions!I18 -> 692628.99
A9: Total current assets | B9: =SUM(B5:B8) -> 4138618 | C9: =SUM(C5:C8) -> 5934289 | D9: =SUM(D5:D8) -> 8358174 | E9: =SUM(E5:E8) -> 12298048 | F9: =SUM(F5:F8) -> 17725186 | G9: =SUM(G5:G8) -> 24837410 | H9: =SUM(H5:H8) -> 33899412 | I9: =SUM(I5:I8) -> 45197744
A10: Property and equipment, net | B10: 47758 | C10: 39638 | D10: 51960 | E10: =D10-'Cash Flow'!E17-'Cash Flow'!E6 -> 80682.558 | F10: =E10-'Cash Flow'!F17-'Cash Flow'!F6 -> 121974.67 | G10: =F10-'Cash Flow'!G17-'Cash Flow'!G6 -> 163962.47 | H10: =G10-'Cash Flow'!H17-'Cash Flow'!H6 -> 218023.33 | I10: =H10-'Cash Flow'!I17-'Cash Flow'!I6 -> 262709.07
A11: Operating lease right-of-use assets | B11: 182863 | C11: 200740 | D11: 200105 | E11: =D11 -> 200105 | F11: =E11 -> 200105 | G11: =F11 -> 200105 | H11: =G11 -> 200105 | I11: =H11 -> 200105
A12: Other assets | B12: 153186 | C12: 166217 | D12: 290153 | E12: ='Income Statement'!E4*Assumptions!E19 -> 466741.57 | F12: ='Income Statement'!F4*Assumptions!F19 -> 670996.86 | G12: ='Income Statement'!G4*Assumptions!G19 -> 909735.58 | H12: ='Income Statement'!H4*Assumptions!H19 -> 1171318.6 | I12: ='Income Statement'!I4*Assumptions!I19 -> 1452286.6
A13: Total assets | B13: =B9+B10+B11+B12 -> 4522425 | C13: =C9+C10+C11+C12 -> 6340884 | D13: =D9+D10+D11+D12 -> 8900392 | E13: =E9+E10+E11+E12 -> 13045578 | F13: =F9+F10+F11+F12 -> 18718263 | G13: =G9+G10+G11+G12 -> 26111213 | H13: =H9+H10+H11+H12 -> 35488859 | I13: =I9+I10+I11+I12 -> 47112845
A15: Liabilities
A16: Accounts payable | B16: 12122 | C16: 103 | D16: 8064 | E16: =('Income Statement'!E5+'Income Statement'!E12)*Assumptions!E20 -> 13518.804 | F16: =('Income Statement'!F5+'Income Statement'!F12)*Assumptions!F20 -> 18213.966 | G16: =('Income Statement'!G5+'Income Statement'!G12)*Assumptions!G20 -> 23343.252 | H16: =('Income Statement'!H5+'Income Statement'!H12)*Assumptions!H20 -> 28611.142 | I16: =('Income Statement'!I5+'Income Statement'!I12)*Assumptions!I20 -> 33765.103
A17: Accrued liabilities | B17: 222991 | C17: 427046 | D17: 355624 | E17: =('Income Statement'!E5+'Income Statement'!E12)*Assumptions!E21 -> 518220.81 | F17: =('Income Statement'!F5+'Income Statement'!F12)*Assumptions!F21 -> 686059.37 | G17: =('Income Statement'!G5+'Income Statement'!G12)*Assumptions!G21 -> 863700.32 | H17: =('Income Statement'!H5+'Income Statement'!H12)*Assumptions!H21 -> 1039538.2 | I17: =('Income Statement'!I5+'Income Statement'!I12)*Assumptions!I21 -> 1204288.7
A18: Deferred revenue | B18: 246901 | C18: 259624 | D18: 408963 | E18: ='Income Statement'!E4*Assumptions!E22 -> 653438.19 | F18: ='Income Statement'!F4*Assumptions!F22 -> 939395.6 | G18: ='Income Statement'!G4*Assumptions!G22 -> 1273629.8 | H18: ='Income Statement'!H4*Assumptions!H22 -> 1639846 | I18: ='Income Statement'!I4*Assumptions!I22 -> 2033201.2
A19: Customer deposits | B19: 209828 | C19: 265252 | D19: 357066 | E19: ='Income Statement'!E4*Assumptions!E24 -> 567270.52 | F19: ='Income Statement'!F4*Assumptions!F24 -> 805196.23 | G19: ='Income Statement'!G4*Assumptions!G24 -> 1077686.8 | H19: ='Income Statement'!H4*Assumptions!H24 -> 1369541.7 | I19: ='Income Statement'!I4*Assumptions!I24 -> 1675715.3
A20: Operating lease liabilities | B20: 54176 | C20: 43993 | D20: 45864 | E20: =D20 -> 45864 | F20: =E20 -> 45864 | G20: =F20 -> 45864 | H20: =G20 -> 45864 | I20: =H20 -> 45864
A21: Total current liabilities | B21: =SUM(B16:B20) -> 746018 | C21: =SUM(C16:C20) -> 996018 | D21: =SUM(D16:D20) -> 1175581 | E21: =SUM(E16:E20) -> 1798312.3 | F21: =SUM(F16:F20) -> 2494729.2 | G21: =SUM(G16:G20) -> 3284224.1 | H21: =SUM(H16:H20) -> 4123401 | I21: =SUM(I16:I20) -> 4992834.3
A22: Deferred revenue, noncurrent | B22: 28047 | C22: 39885 | D22: 46216 | E22: ='Income Statement'!E4*Assumptions!E23 -> 71806.395 | F22: ='Income Statement'!F4*Assumptions!F23 -> 103230.29 | G22: ='Income Statement'!G4*Assumptions!G23 -> 139959.32 | H22: ='Income Statement'!H4*Assumptions!H23 -> 180202.86 | I22: ='Income Statement'!I4*Assumptions!I23 -> 223428.71
A23: Customer deposits, noncurrent | B23: 1477 | C23: 1663 | D23: 18 | E23: =D23 -> 18 | F23: =E23 -> 18 | G23: =F23 -> 18 | H23: =G23 -> 18 | I23: =H23 -> 18
A24: Operating lease liabilities, noncurrent | B24: 175216 | C24: 195226 | D24: 183474 | E24: =D24 -> 183474 | F24: =E24 -> 183474 | G24: =F24 -> 183474 | H24: =G24 -> 183474 | I24: =H24 -> 183474
A25: Other noncurrent liabilities | B25: 10702 | C25: 13685 | D25: 7092 | E25: =D25 -> 7092 | F25: =E25 -> 7092 | G25: =F25 -> 7092 | H25: =G25 -> 7092 | I25: =H25 -> 7092
A26: Total liabilities | B26: =B21+SUM(B22:B25) -> 961460 | C26: =C21+SUM(C22:C25) -> 1246477 | D26: =D21+SUM(D22:D25) -> 1412381 | E26: =E21+SUM(E22:E25) -> 2060702.7 | F26: =F21+SUM(F22:F25) -> 2788543.4 | G26: =G21+SUM(G22:G25) -> 3614767.5 | H26: =H21+SUM(H22:H25) -> 4494187.9 | I26: =I21+SUM(I22:I25) -> 5406847
A28: Stockholders' equity
A29: Common stock | B29: 2200 | C29: 2339 | D29: 2391 | E29: =D29 -> 2391 | F29: =E29 -> 2391 | G29: =F29 -> 2391 | H29: =G29 -> 2391 | I29: =H29 -> 2391
A30: Additional paid-in capital | B30: 9122173 | C30: 10193970 | D30: 10933325 | E30: =D30+'Cash Flow'!E7+'Cash Flow'!E23 -> 12016808 | F30: =E30+'Cash Flow'!F7+'Cash Flow'!F23 -> 13353956 | G30: =F30+'Cash Flow'!G7+'Cash Flow'!G23 -> 14931541 | H30: =G30+'Cash Flow'!H7+'Cash Flow'!H23 -> 16757428 | I30: =H30+'Cash Flow'!I7+'Cash Flow'!I23 -> 18828915
A31: Accumulated other comprehensive income (loss) | B31: 801 | C31: -5611 | D31: 13942 | E31: =D31 -> 13942 | F31: =E31 -> 13942 | G31: =F31 -> 13942 | H31: =G31 -> 13942 | I31: =H31 -> 13942
A32: Accumulated deficit | B32: -5649613 | C32: -5187423 | D32: -3562390 | E32: =D32+'Income Statement'!E21+'Cash Flow'!E24+'Cash Flow'!E25 -> -1149009.3 | F32: =E32+'Income Statement'!F21+'Cash Flow'!F24+'Cash Flow'!F25 -> 2458686.8 | G32: =F32+'Income Statement'!G21+'Cash Flow'!G24+'Cash Flow'!G25 -> 7447828.5 | H32: =G32+'Income Statement'!H21+'Cash Flow'!H24+'Cash Flow'!H25 -> 14120167 | I32: =H32+'Income Statement'!I21+'Cash Flow'!I24+'Cash Flow'!I25 -> 22760007
A33: Total Palantir stockholders' equity | B33: =SUM(B29:B32) -> 3475561 | C33: =SUM(C29:C32) -> 5003275 | D33: =SUM(D29:D32) -> 7387268 | E33: =SUM(E29:E32) -> 10884132 | F33: =SUM(F29:F32) -> 15828976 | G33: =SUM(G29:G32) -> 22395703 | H33: =SUM(H29:H32) -> 30893928 | I33: =SUM(I29:I32) -> 41605255
A34: Noncontrolling interests | B34: 85404 | C34: 91132 | D34: 100743 | E34: =D34 -> 100743 | F34: =E34 -> 100743 | G34: =F34 -> 100743 | H34: =G34 -> 100743 | I34: =H34 -> 100743
A35: Total equity | B35: =B33+B34 -> 3560965 | C35: =C33+C34 -> 5094407 | D35: =D33+D34 -> 7488011 | E35: =E33+E34 -> 10984875 | F35: =F33+F34 -> 15929719 | G35: =G33+G34 -> 22496446 | H35: =H33+H34 -> 30994671 | I35: =I33+I34 -> 41705998
A36: Total liabilities and equity | B36: =B26+B35 -> 4522425 | C36: =C26+C35 -> 6340884 | D36: =D26+D35 -> 8900392 | E36: =E26+E35 -> 13045578 | F36: =F26+F35 -> 18718263 | G36: =G26+G35 -> 26111213 | H36: =H26+H35 -> 35488859 | I36: =I26+I35 -> 47112845
A38: Balance check (assets − liabilities & equity) | B38: =B13-B36 -> 0 | C38: =C13-C36 -> 0 | D38: =D13-D36 -> 0 | E38: =E13-E36 -> 0 | F38: =F13-F36 -> 0 | G38: =G13-G36 -> 0 | H38: =H13-H36 -> 0 | I38: =I13-I36 -> 0 | K38: Must be zero in every period

Sheet Cash Flow
A1: Palantir Technologies Inc.; Statement of Cash Flows
A2: (USD in thousands, except per-share amounts) · FY2023A–FY2025A per SEC filings · FY2026E–FY2030E forecast
B3: FY2023A | C3: FY2024A | D3: FY2025A | E3: FY2026E | F3: FY2027E | G3: FY2028E | H3: FY2029E | I3: FY2030E
A4: Operating activities
A5: Net income | B5: 217375 | C5: 467918 | D5: 1634644 | E5: ='Income Statement'!E19 -> 2813380.7 | F5: ='Income Statement'!F19 -> 4107696.1 | G5: ='Income Statement'!G19 -> 5589141.7 | H5: ='Income Statement'!H19 -> 7372338.7 | I5: ='Income Statement'!I19 -> 9439839.6
A6: Depreciation and amortization | B6: 33354 | C6: 31587 | D6: 26145 | E6: ='Income Statement'!E27 -> 43083.837 | F6: ='Income Statement'!F27 -> 61938.171 | G6: ='Income Statement'!G27 -> 83975.592 | H6: ='Income Statement'!H27 -> 108121.71 | I6: ='Income Statement'!I27 -> 134057.22
A7: Stock-based compensation | B7: 475903 | C7: 691638 | D7: 684033 | E7: ='Income Statement'!E26 -> 933483.13 | F7: ='Income Statement'!F26 -> 1187148.3 | G7: ='Income Statement'!G26 -> 1427585.1 | H7: ='Income Statement'!H26 -> 1675886.6 | I7: ='Income Statement'!I26 -> 1921486.9
A8: Other non-cash adjustments, net | B8: -20685 | C8: 32819 | D8: -386 | E8: 0 | F8: 0 | G8: 0 | H8: 0 | I8: 0 | K8: Historical: unrealized securities losses, noncash consideration and other items, per filings
A9: (Increase) in accounts receivable | B9: -106159 | C9: -211157 | D9: -450429 | E9: =-('Balance Sheet'!E7-'Balance Sheet'!D7) -> -630138.72 | F9: =-('Balance Sheet'!F7-'Balance Sheet'!E7) -> -703506.96 | G9: =-('Balance Sheet'!G7-'Balance Sheet'!F7) -> -806925.91 | H9: =-('Balance Sheet'!H7-'Balance Sheet'!G7) -> -865756.38 | I9: =-('Balance Sheet'!I7-'Balance Sheet'!H7) -> -909887.92
A10: (Increase) decrease in prepaid and other assets | B10: -2955 | C10: 11883 | D10: 51979 | E10: =-('Balance Sheet'!E8-'Balance Sheet'!D8)-('Balance Sheet'!E12-'Balance Sheet'!D12) -> -260122.39 | F10: =-('Balance Sheet'!F8-'Balance Sheet'!E8)-('Balance Sheet'!F12-'Balance Sheet'!E12) -> -301669.35 | G10: =-('Balance Sheet'!G8-'Balance Sheet'!F8)-('Balance Sheet'!G12-'Balance Sheet'!F12) -> -352598.73 | H10: =-('Balance Sheet'!H8-'Balance Sheet'!G8)-('Balance Sheet'!H12-'Balance Sheet'!G12) -> -386337.96 | I10: =-('Balance Sheet'!I8-'Balance Sheet'!H8)-('Balance Sheet'!I12-'Balance Sheet'!H12) -> -414968.15
A11: Increase (decrease) in AP and accrued liabilities | B11: 21063 | C11: 96793 | D11: 4659 | E11: =('Balance Sheet'!E16-'Balance Sheet'!D16)+('Balance Sheet'!E17-'Balance Sheet'!D17) -> 168051.61 | F11: =('Balance Sheet'!F16-'Balance Sheet'!E16)+('Balance Sheet'!F17-'Balance Sheet'!E17) -> 172533.72 | G11: =('Balance Sheet'!G16-'Balance Sheet'!F16)+('Balance Sheet'!G17-'Balance Sheet'!F17) -> 182770.24 | H11: =('Balance Sheet'!H16-'Balance Sheet'!G16)+('Balance Sheet'!H17-'Balance Sheet'!G17) -> 181105.74 | I11: =('Balance Sheet'!I16-'Balance Sheet'!H16)+('Balance Sheet'!I17-'Balance Sheet'!H17) -> 169904.46
A12: Increase in deferred revenue and customer deposits | B12: 143859 | C12: 76796 | D12: 238688 | E12: =('Balance Sheet'!E18-'Balance Sheet'!D18)+('Balance Sheet'!E22-'Balance Sheet'!D22)+('Balance Sheet'!E19-'Balance Sheet'!D19)+('Balance Sheet'!E23-'Balance Sheet'!D23) -> 480270.11 | F12: =('Balance Sheet'!F18-'Balance Sheet'!E18)+('Balance Sheet'!F22-'Balance Sheet'!E22)+('Balance Sheet'!F19-'Balance Sheet'!E19)+('Balance Sheet'!F23-'Balance Sheet'!E23) -> 555307 | G12: =('Balance Sheet'!G18-'Balance Sheet'!F18)+('Balance Sheet'!G22-'Balance Sheet'!F22)+('Balance Sheet'!G19-'Balance Sheet'!F19)+('Balance Sheet'!G23-'Balance Sheet'!F23) -> 643453.79 | H12: =('Balance Sheet'!H18-'Balance Sheet'!G18)+('Balance Sheet'!H22-'Balance Sheet'!G22)+('Balance Sheet'!H19-'Balance Sheet'!G19)+('Balance Sheet'!H23-'Balance Sheet'!G23) -> 698314.69 | I12: =('Balance Sheet'!I18-'Balance Sheet'!H18)+('Balance Sheet'!I22-'Balance Sheet'!H22)+('Balance Sheet'!I19-'Balance Sheet'!H19)+('Balance Sheet'!I23-'Balance Sheet'!H23) -> 742754.66
A13: Change in other operating liabilities | B13: -49572 | C13: -44412 | D13: -54860 | E13: 0 | F13: 0 | G13: 0 | H13: 0 | I13: 0
A14: Net cash provided by operating activities | B14: =SUM(B5:B13) -> 712183 | C14: =SUM(C5:C13) -> 1153865 | D14: =SUM(D5:D13) -> 2134473 | E14: =SUM(E5:E13) -> 3548008.2 | F14: =SUM(F5:F13) -> 5079447 | G14: =SUM(G5:G13) -> 6767401.8 | H14: =SUM(H5:H13) -> 8783673.1 | I14: =SUM(I5:I13) -> 11083187
A16: Investing activities
A17: Purchases of property and equipment | B17: -15114 | C17: -12634 | D17: -33882 | E17: =-'Income Statement'!E4*Assumptions!E25 -> -71806.395 | F17: =-'Income Statement'!F4*Assumptions!F25 -> -103230.29 | G17: =-'Income Statement'!G4*Assumptions!G25 -> -125963.39 | H17: =-'Income Statement'!H4*Assumptions!H25 -> -162182.57 | I17: =-'Income Statement'!I4*Assumptions!I25 -> -178742.97
A18: Net (purchases) sales of marketable securities | B18: -2747138 | C18: -322406 | D18: -2675745 | E18: 0 | F18: 0 | G18: 0 | H18: 0 | I18: 0 | K18: Forecast: marketable securities held flat; excess cash retained in cash & equivalents
A19: Other investing activities | B19: 51072 | C19: -5615 | D19: -73924 | E19: 0 | F19: 0 | G19: 0 | H19: 0 | I19: 0
A20: Net cash used in investing activities | B20: =SUM(B17:B19) -> -2711180 | C20: =SUM(C17:C19) -> -340655 | D20: =SUM(D17:D19) -> -2783551 | E20: =SUM(E17:E19) -> -71806.395 | F20: =SUM(F17:F19) -> -103230.29 | G20: =SUM(G17:G19) -> -125963.39 | H20: =SUM(H17:H19) -> -162182.57 | I20: =SUM(I17:I19) -> -178742.97
A22: Financing activities
A23: Proceeds from exercise of stock options | B23: 218238 | C23: 745396 | D23: 129107 | E23: =Assumptions!E29 -> 150000 | F23: =Assumptions!F29 -> 150000 | G23: =Assumptions!G29 -> 150000 | H23: =Assumptions!H29 -> 150000 | I23: =Assumptions!I29 -> 150000
A24: Repurchases of common stock | B24: 0 | C24: -64196 | D24: -74985 | E24: =-Assumptions!E28 -> -300000 | F24: =-Assumptions!F28 -> -400000 | G24: =-Assumptions!G28 -> -500000 | H24: =-Assumptions!H28 -> -600000 | I24: =-Assumptions!I28 -> -700000
A25: Taxes paid on net share settlement of equity awards | B25: 0 | C25: -218280 | D25: -81117 | E25: =-Assumptions!E30 -> -100000 | F25: =-Assumptions!F30 -> -100000 | G25: =-Assumptions!G30 -> -100000 | H25: =-Assumptions!H30 -> -100000 | I25: =-Assumptions!I30 -> -100000
A26: Other financing activities | B26: 601 | C26: 444 | D26: 85 | E26: 0 | F26: 0 | G26: 0 | H26: 0 | I26: 0
A27: Net cash provided by (used in) financing activities | B27: =SUM(B23:B26) -> 218839 | C27: =SUM(C23:C26) -> 463364 | D27: =SUM(D23:D26) -> -26910 | E27: =SUM(E23:E26) -> -250000 | F27: =SUM(F23:F26) -> -350000 | G27: =SUM(G23:G26) -> -450000 | H27: =SUM(H23:H26) -> -550000 | I27: =SUM(I23:I26) -> -650000
A29: Effect of foreign exchange on cash | B29: 2930 | C29: -6745 | D29: 7477 | E29: 0 | F29: 0 | G29: 0 | H29: 0 | I29: 0
A30: Net increase (decrease) in cash | B30: =B14+B20+B27+B29 -> -1777228 | C30: =C14+C20+C27+C29 -> 1269829 | D30: =D14+D20+D27+D29 -> -668511 | E30: =E14+E20+E27+E29 -> 3226201.8 | F30: =F14+F20+F27+F29 -> 4626216.7 | G30: =G14+G20+G27+G29 -> 6191438.4 | H30: =H14+H20+H27+H29 -> 8071490.5 | I30: =I14+I20+I27+I29 -> 10254444
A31: Cash, equivalents and restricted cash, beginning | B31: 2627335 | C31: 850107 | D31: 2119936 | E31: =D34 -> 1423796 | F31: =E34 -> 4649997.8 | G31: =F34 -> 9276214.5 | H31: =G34 -> 15467653 | I31: =H34 -> 23539143
A32: Cash, equivalents and restricted cash, ending | B32: =B31+B30 -> 850107 | C32: =C31+C30 -> 2119936 | D32: =D31+D30 -> 1451425 | E32: =E31+E30 -> 4649997.8 | F32: =F31+F30 -> 9276214.5 | G32: =G31+G30 -> 15467653 | H32: =H31+H30 -> 23539143 | I32: =I31+I30 -> 33793587
A33: Less: restricted cash | B33: 19060 | C33: 21412 | D33: 27629 | E33: 0 | F33: 0 | G33: 0 | H33: 0 | I33: 0
A34: Cash and cash equivalents per balance sheet | B34: =B32-B33 -> 831047 | C34: =C32-C33 -> 2098524 | D34: =D32-D33 -> 1423796 | E34: =E32-E33 -> 4649997.8 | F34: =F32-F33 -> 9276214.5 | G34: =G32-G33 -> 15467653 | H34: =H32-H33 -> 23539143 | I34: =I32-I33 -> 33793587 | K34: Links to cash on the balance sheet

Sheet Budget vs Actual
A1: Palantir Technologies Inc.; Budget vs Actual Variance
A2: FY2025 actual vs FY2025 budget (USD in thousands, except per-share) · Budget seeded from company guidance where published; all budget cells editable
A4: Variance flag threshold (|variance %| above this is flagged) | B4: 0.1
A6: Metric | B6: FY2025 Budget | C6: Budget source | D6: Override budget | E6: Effective budget | F6: FY2025 Actual | G6: Variance $ | H6: Variance % | I6: Flag
A7: Revenue | B7: 3749000 | C7: Company FY25 guidance (Feb 3, 2025): $3,741–3,757M | E7: =IF(D7="",B7,D7) -> 3749000 | F7: ='Income Statement'!D4 -> 4475446 | G7: =F7-E7 -> 726446 | H7: =IF(E7=0,"",G7/E7) -> 0.19377061 | I7: =IF(H7="","",IF(ABS(H7)>$B$4,"⚠ REVIEW","OK")) -> ⚠ REVIEW
A8: Gross profit | B8: 3075000 | C8: Placeholder · replace with your budget | E8: =IF(D8="",B8,D8) -> 3075000 | F8: ='Income Statement'!D6 -> 3686269 | G8: =F8-E8 -> 611269 | H8: =IF(E8=0,"",G8/E8) -> 0.19878667 | I8: =IF(H8="","",IF(ABS(H8)>$B$4,"⚠ REVIEW","OK")) -> ⚠ REVIEW
A9: Total operating expenses | B9: 2150000 | C9: Placeholder · replace with your budget | E9: =IF(D9="",B9,D9) -> 2150000 | F9: ='Income Statement'!D12 -> 2272254 | G9: =F9-E9 -> 122254 | H9: =IF(E9=0,"",G9/E9) -> 0.056862326 | I9: =IF(H9="","",IF(ABS(H9)>$B$4,"⚠ REVIEW","OK")) -> OK
A10: Income from operations (GAAP) | B10: 925000 | C10: Placeholder (guidance was directional only) | E10: =IF(D10="",B10,D10) -> 925000 | F10: ='Income Statement'!D13 -> 1414015 | G10: =F10-E10 -> 489015 | H10: =IF(E10=0,"",G10/E10) -> 0.52866486 | I10: =IF(H10="","",IF(ABS(H10)>$B$4,"⚠ REVIEW","OK")) -> ⚠ REVIEW
A11: Net income to common (GAAP) | B11: 1050000 | C11: Placeholder · replace with your budget | E11: =IF(D11="",B11,D11) -> 1050000 | F11: ='Income Statement'!D21 -> 1625033 | G11: =F11-E11 -> 575033 | H11: =IF(E11=0,"",G11/E11) -> 0.54765048 | I11: =IF(H11="","",IF(ABS(H11)>$B$4,"⚠ REVIEW","OK")) -> ⚠ REVIEW
A12: Adjusted income from operations | B12: 1559000 | C12: Company FY25 guidance: $1,551–1,567M | E12: =IF(D12="",B12,D12) -> 1559000 | F12: 2254100 | G12: =F12-E12 -> 695100 | H12: =IF(E12=0,"",G12/E12) -> 0.44586273 | I12: =IF(H12="","",IF(ABS(H12)>$B$4,"⚠ REVIEW","OK")) -> ⚠ REVIEW
A13: Net cash provided by operating activities | B13: 1800000 | C13: Placeholder · replace with your budget | E13: =IF(D13="",B13,D13) -> 1800000 | F13: ='Cash Flow'!D14 -> 2134473 | G13: =F13-E13 -> 334473 | H13: =IF(E13=0,"",G13/E13) -> 0.18581833 | I13: =IF(H13="","",IF(ABS(H13)>$B$4,"⚠ REVIEW","OK")) -> ⚠ REVIEW
A14: Adjusted free cash flow | B14: 1600000 | C14: Company FY25 guidance: $1.5–1.7B | E14: =IF(D14="",B14,D14) -> 1600000 | F14: 2270436 | G14: =F14-E14 -> 670436 | H14: =IF(E14=0,"",G14/E14) -> 0.4190225 | I14: =IF(H14="","",IF(ABS(H14)>$B$4,"⚠ REVIEW","OK")) -> ⚠ REVIEW
A15: Diluted EPS (GAAP, $) | B15: 0.42 | C15: Placeholder · replace with your budget | E15: =IF(D15="",B15,D15) -> 0.42 | F15: ='Income Statement'!D24 -> 0.63349248 | G15: =F15-E15 -> 0.21349248 | H15: =IF(E15=0,"",G15/E15) -> 0.50831542 | I15: =IF(H15="","",IF(ABS(H15)>$B$4,"⚠ REVIEW","OK")) -> ⚠ REVIEW
A17: Notes:
A18: • Budget column is seeded with the midpoint of company guidance issued at the start of FY2025 where published (see Budget source).
A19: • Rows marked "Placeholder" carry illustrative budgets; overwrite them, or type your own number in the yellow Override column (it takes precedence).
A20: • GAAP actuals pull live from the statement tabs (green); non-GAAP actuals are per the company's Q4 FY2025 earnings release.
A21: • Rows turn red automatically when |Variance %| exceeds the threshold in B4.

Sheet Market Inputs
A1: Palantir Technologies Inc.; Market Inputs
A2: Snapshot as of market close July 17, 2026 · All values are inputs (blue); see REFRESH section to wire live updates
A4: Data as of: | B4: July 17, 2026 | C4: Last refreshed: | D4: 2026-07-20 (initial snapshot)
A6: INTEREST RATES
A7: Fed funds target (upper bound) | B7: 0.0375 | F7: Range 3.50%–3.75%; unchanged at June 17, 2026 FOMC
A8: SOFR | B8: 0.0364 | F8: NY Fed, latest print
A9: 3-month T-bill (CMT) | B9: 0.0384 | F9: Fed H.15, Jul 16, 2026
A10: 2-year Treasury | B10: 0.0418 | F10: Close Jul 17, 2026
A11: 10-year Treasury | B11: 0.0455 | F11: Close Jul 17, 2026
A12: 30-year Treasury | B12: 0.0506 | F12: Close Jul 17, 2026
A14: EQUITY MARKET DATA: PEER SET
B15: PLTR | C15: HUBS | D15: SOFI
A16: Share price ($) | B16: 132.38 | C16: 224.26 | D16: 17.28
A17: Market cap ($mm) | B17: 317400 | C17: 11490 | D17: 22170
A18: Enterprise value ($mm) | B18: 309500 | C18: 10040 | D18: 20520
A19: Trailing P/E (x) | B19: 148.8 | C19: 119.2 | D19: 38.8
A20: Forward P/E (x) | B20: 83.3 | C20: 16.4 | D20: 26.4
A21: EV / Revenue, TTM (x) | B21: 59.3 | C21: 3 | D21: 5.2
A22: TTM revenue ($mm) | B22: 5220 | C22: 3300 | D22: 3910
A24: IMPLIED VALUATION CROSS-CHECK (uses this model's forecast)
A25: Selected EV / Revenue multiple (x) | B25: =B21 -> 59.3 | F25: Defaults to this company's current multiple; flex it or use a peer's
A26: Model FY2026E revenue ($000s) | B26: ='Income Statement'!E4 -> 7180639.5
A27: Implied enterprise value ($mm) | B27: =B25*B26/1000 -> 425811.92
A28: Current enterprise value ($mm) | B28: =B18 -> 309500
A29: Implied premium / (discount) to current EV | B29: =B27/B28-1 -> 0.37580589
A31: Selected forward P/E multiple (x) | B31: =B20 -> 83.3 | F31: Defaults to this company's current multiple; flex it or use a peer's
A32: Model FY2026E net income ($000s) | B32: ='Income Statement'!E21 -> 2813380.7
A33: Implied market capitalization ($mm) | B33: =B31*B32/1000 -> 234354.61
A34: Current market capitalization ($mm) | B34: =B17 -> 317400
A35: Implied premium / (discount) to current market cap | B35: =B33/B34-1 -> -0.26164269
A37: REFRESH: MAKE THIS TAB LIVE (one-time setup, ~2 minutes in Excel)
A38: 1. Excel ▸ Data ▸ Get Data (Power Query) ▸ From Other Sources ▸ From Web.
A39: 2. Treasury yields (CSV, no key needed): https://home.treasury.gov/resource-center/data-chart-center/interest-rates/daily-treasury-rates.csv/2026/all?type=daily_treasury_yield_curve&field_tdr_date_value=2026&page&_format=csv
A40: 3. Load the query to a new sheet; point the blue rate cells above at the latest row (e.g. =INDEX(...)).
A41: 4. Share prices (JSON): https://query1.finance.yahoo.com/v8/finance/chart/PLTR ; Power Query ▸ From Web, drill to chart.result.meta.regularMarketPrice.
A42: 5. After setup, Data ▸ Refresh All re-pulls everything with one click.
A43: 6. Until then this tab is a dated snapshot (see B4); or ask Claude to refresh the numbers any time.
A44: Sources for this snapshot: Fed H.15 (Jul 17, 2026), NY Fed SOFR, stockanalysis.com / S&P Global (Jul 17–19, 2026).

Sheet Competitor Benchmarking
A1: Palantir Technologies Inc.; Competitor Benchmarking
A2: Company column pulls live from this model (FY2025 actuals; FY2026E is scenario-aware) · comps per latest reported fiscal year, valuations as of July 17–20, 2026 · industry benchmarks: Clouded Judgement SaaS medians (7/10/26) and US bank norms
A4: Metric | B4: Palantir (model) | C4: Snowflake (SNOW, FY ended 1/26) | D4: Datadog (DDOG, FY2025) | E4: Peer median | F4: Industry benchmark | H4: What it means
A5: Latest FY revenue ($mm) | B5: ='Income Statement'!D4/1000 -> 4475.446 | C5: 4684 | D5: 3427 | E5: =MEDIAN(B5:D5) -> 4475.446 | F5: — | H5: Palantir is now in the same revenue class as Snowflake, with a materially better P&L.
A6: Revenue growth · FY2025 % | B6: ='Income Statement'!D4/'Income Statement'!C4-1 -> 0.56183391 | C6: 0.29 | D6: 0.28 | E6: =MEDIAN(B6:D6) -> 0.29 | F6: 0.13 | H6: 56% growth is ~2x the fastest data-platform comps and ~4x the SaaS median; the core justification for the outlier multiple.
A7: Revenue growth · FY2026E (model, scenario-aware) % | B7: ='Income Statement'!E4/'Income Statement'!D4-1 -> 0.60445227 | C7: n/a | D7: n/a | F7: — | H7: Model FY26E growth (scenario-aware) tracks management guidance of +61%; comps consensus sits in the mid-20s.
A8: GAAP gross margin · FY2025 % | B8: ='Income Statement'!D6/'Income Statement'!D4 -> 0.82366517 | C8: 0.672 | D8: 0.8 | E8: =MEDIAN(B8:D8) -> 0.8 | F8: 0.76 | H8: Above the 76% SaaS median and both comps even while absorbing AI compute; see the compute block on Revenue Drivers.
A9: GAAP operating margin · FY2025 % | B9: ='Income Statement'!D13/'Income Statement'!D4 -> 0.31594952 | C9: -0.31 | D9: -0.01 | E9: =MEDIAN(B9:D9) -> -0.01 | F9: 0.02 | H9: GAAP-profitable at a 32% margin while SNOW (-31%) and DDOG (-1%) are at or below GAAP breakeven; rare at this growth rate.
A10: Free cash flow margin · FY2025 % | B10: =('Cash Flow'!D14+'Cash Flow'!D17)/'Income Statement'!D4 -> 0.46935903 | C10: 0.25 | D10: 0.27 | E10: =MEDIAN(B10:D10) -> 0.27 | F10: 0.21 | H10: 47% GAAP FCF margin more than doubles the comps and the 21% median.
A11: Rule of 40 (growth + FCF margin) | B11: =B6+B10 -> 1.0311929 | C11: =C6+C10 -> 0.54 | D11: =D6+D10 -> 0.55 | E11: =MEDIAN(B11:D11) -> 0.55 | F11: 0.34 | H11: Rule of 40 at ~103% vs a ~34% median; almost no public software company clears 100%.
A12: EV / Revenue (TTM) (x) | B12: ='Market Inputs'!B18/'Market Inputs'!B22 -> 59.291188 | C12: 18.2 | D12: 24.1 | E12: =MEDIAN(B12:D12) -> 24.1 | F12: 20.3 | H12: 59x TTM revenue is ~3x even the high-growth bucket median (20.3x); the valuation cross-check on Market Inputs shows the beats needed to grow into it.
A13: Forward P/E (x, non-GAAP consensus basis) | B13: ='Market Inputs'!B20 -> 83.3 | C13: 127.2 | D13: 105 | E13: =MEDIAN(B13:D13) -> 105 | F13: ~21x S&P 500 | H13: Cheaper per dollar of forward earnings than SNOW/DDOG, but ~4x the S&P; priced for sustained hypergrowth.
A15: INDUSTRY BENCHMARK NOTES
A16: • SaaS medians per Clouded Judgement (Altimeter, 7/10/26): NTM growth 13% · GAAP gross margin 76% · operating margin 2% · FCF margin 21% · NRR 110% · EV/NTM revenue: overall 3.5x, high-growth (>22%) 20.3x, mid-growth (15–22%) 5.4x, low-growth 2.8x.
A17: • Rule of 40 = revenue growth % + FCF margin % ≥ 40% is the standard bar for a healthy software business.
A19: TAKEAWAYS: WHAT THIS COMPARISON MEANS
A20: • Palantir screens as the highest-quality operator in the peer set: fastest growth, best GAAP margins, and a Rule of 40 (~103%) roughly 3x the industry median.
A21: • The debate is entirely valuation: at ~59x TTM revenue vs a 20.3x high-growth bucket median, the stock discounts years of continued 40%+ growth; stress this with the Low Case regional scenario.
A22: • Versus SNOW and DDOG, Palantir converts growth to profit far more efficiently; versus the market, its multiple leaves no room for a growth stumble.
A24: Sources: company Q4/FY earnings releases and 10-Ks (SEC EDGAR); stockanalysis.com / S&P Global valuations Jul 17–20, 2026; cloudedjudgement.substack.com 7/10/26; multiples.vc Jul 2026. Comp forward P/Es are consensus (non-GAAP) based.

Sheet Version History
A1: Palantir Technologies Inc.; Version History
A2: Log of every assumptions refresh: what changed, when, and why. Add a new row each time inputs are updated.
A4: Version | B4: Date | C4: Changed by | D4: What changed | E4: Why
