Workbook

Sheet Cover
B2: SOFI TECHNOLOGIES, INC. (NASDAQ: SOFI)
B3: Three-Statement Financial Model — Fintech — Digital Banking & Lending (Bank Holding Company)
B4: Integrated Income Statement · Balance Sheet · Cash Flow · driver-based forecast · regional scenarios · live market data
B6: AUTHOR & VERSION
B7: Prepared by: Avash Pardhootman
B8: =HYPERLINK("mailto:avash.pardhootman@gmail.com","Contact: avash.pardhootman@gmail.com") -> Contact: avash.pardhootman@gmail.com
B9: =HYPERLINK("https://www.linkedin.com/in/avashpardhootman/","LinkedIn: linkedin.com/in/avashpardhootman") -> LinkedIn: linkedin.com/in/avashpardhootman
B10: Date: July 2026 · Model version: 1.7 (see Version History) · Units: USD thousands, except per-share
B11: Periods: FY2023–FY2025 actual (per SEC filings) · FY2026–FY2030 forecast
B13: QUICK LINKS
B14: =HYPERLINK("Finance_AI_Dashboard.html","▸ Interactive dashboard — toggle industry, scenario and region in your browser (same folder)") -> ▸ Interactive dashboard — toggle industry, scenario and region in your browser (same folder)
B15: =HYPERLINK("README.md","▸ Portfolio README — overview of all three models and how they fit together") -> ▸ Portfolio README — overview of all three models and how they fit together
B16: =HYPERLINK("refresh_market_data.py","▸ Market-data refresh script — run to update prices, rates and refresh stamps everywhere") -> ▸ Market-data refresh script — run to update prices, rates and refresh stamps everywhere
B18: CONTENTS
B19: =HYPERLINK("#'Assumptions'!A1","▸ Assumptions — Margin, tax, working-capital and financing drivers") -> ▸ Assumptions — Margin, tax, working-capital and financing drivers
B20: =HYPERLINK("#'Revenue Drivers'!A1","▸ Revenue Drivers — Bottoms-up sector build driving revenue and key costs") -> ▸ Revenue Drivers — Bottoms-up sector build driving revenue and key costs
B21: =HYPERLINK("#'Regional Breakdown'!A1","▸ Regional Breakdown — NA / Europe / APAC splits and the Standard / Best / Low case selector") -> ▸ Regional Breakdown — NA / Europe / APAC splits and the Standard / Best / Low case selector
B22: =HYPERLINK("#'Income Statement'!A1","▸ Income Statement — Revenue build-down to EPS") -> ▸ Income Statement — Revenue build-down to EPS
B23: =HYPERLINK("#'Balance Sheet'!A1","▸ Balance Sheet — Assets, liabilities and equity, with balance check") -> ▸ Balance Sheet — Assets, liabilities and equity, with balance check
B24: =HYPERLINK("#'Cash Flow'!A1","▸ Cash Flow — Indirect-method cash flow; ending cash links to the balance sheet") -> ▸ Cash Flow — Indirect-method cash flow; ending cash links to the balance sheet
B25: =HYPERLINK("#'Budget vs Actual'!A1","▸ Budget vs Actual — FY2025 vs guidance with automatic >10% variance flagging") -> ▸ Budget vs Actual — FY2025 vs guidance with automatic >10% variance flagging
B26: =HYPERLINK("#'Market Inputs'!A1","▸ Market Inputs — Rates and valuation multiples with refresh stamps") -> ▸ Market Inputs — Rates and valuation multiples with refresh stamps
B27: =HYPERLINK("#'Competitor Benchmarking'!A1","▸ Competitor Benchmarking — Two public comps + peer median + industry benchmarks") -> ▸ Competitor Benchmarking — Two public comps + peer median + industry benchmarks
B28: =HYPERLINK("#'Version History'!A1","▸ Version History — Audit log of every assumptions and data refresh") -> ▸ Version History — Audit log of every assumptions and data refresh
B29: =HYPERLINK("#'Sources'!A1","▸ Sources — Where every input comes from — citations, links, last-updated dates") -> ▸ Sources — Where every input comes from — citations, links, last-updated dates
B31: HOW TO USE THIS MODEL
B32: 1. Start on the Revenue Drivers and Assumptions tabs — every blue cell is an input; yellow cells are the key levers.
B33: 2. Flip the scenario selector on Regional Breakdown (1 = Standard · 2 = Best Case · 3 = Low Case) — the whole model re-runs, including EPS, cash and the benchmarking tab.
B34: 3. Check Budget vs Actual for FY2025 performance vs guidance; rows over the 10% threshold flag automatically.
B35: 4. Keep market data current: run refresh_market_data.py in this folder (or use the dashboard ⟳ button) — stamps update on Market Inputs and the refresh is logged in Version History.
B36: 5. For a browser walkthrough or a one-page memo, open Finance_AI_Dashboard.html and use Export memo (PDF).
B38: MODEL NOTES
B39: • FY2023–FY2025 as reported; bank-style statement structure (net interest income + noninterest income, provision below net revenue per current presentation).
B40: • Fee revenue is built from originations × take rates on the Revenue Drivers tab; delinquency and charge-off trends inform the provision.
B41: • FY2024 tax benefit reflects a one-time valuation-allowance release; forecast normalizes at 25%. Balance sheet balances in all periods under every scenario.
B43: COLOR CONVENTIONS
B44: Blue — hardcoded input (historical figures as reported; forecast assumptions)
... B48: Every data input is cited on the Sources tab, with links and last-updated dates.

Sheet Assumptions
A1: SoFi Technologies, Inc. — Forecast Assumptions
A2: (USD in thousands, except per-share amounts) · FY2023A–FY2025A per SEC filings · FY2026E–FY2030E forecast
B3: FY2023A | C3: FY2024A | D3: FY2025A | E3: FY2026E | F3: FY2027E | G3: FY2028E | H3: FY2029E | I3: FY2030E
A4: Balance sheet growth drivers
A5: Interest-bearing deposit growth % | C5: ='Balance Sheet'!C20/'Balance Sheet'!B20-1 -> 0.39271957 | D5: ='Balance Sheet'!D20/'Balance Sheet'!C20-1 -> 0.44568159 | E5: 0.28 | F5: 0.24 | G5: 0.2 | H5: 0.17 | I5: 0.15 | K5: SoFi Money momentum moderates from FY25's 44.6%; funds loan growth
A6: Loans held for sale growth % | C6: ='Balance Sheet'!C8/'Balance Sheet'!B8-1 -> 0.14861045 | D6: ='Balance Sheet'!D8/'Balance Sheet'!C8-1 -> 0.2927842 | E6: 0.2 | F6: 0.18 | G6: 0.15 | H6: 0.13 | I6: 0.12 | K6: Personal-loan originations; loan platform business shifts volume off balance sheet
A7: Loans held for investment (fair value) growth % | C7: ='Balance Sheet'!C9/'Balance Sheet'!B9-1 -> 0.27832703 | D7: ='Balance Sheet'!D9/'Balance Sheet'!C9-1 -> 0.58857664 | E7: 0.3 | F7: 0.25 | G7: 0.2 | H7: 0.18 | I7: 0.15
A8: Loans held for investment (amortized cost) growth % | C8: ='Balance Sheet'!C10/'Balance Sheet'!B10-1 -> 0.49069495 | D8: ='Balance Sheet'!D10/'Balance Sheet'!C10-1 -> 0.21683683 | E8: 0.18 | F8: 0.16 | G8: 0.15 | H8: 0.13 | I8: 0.12
A9: Investment securities growth % | C9: ='Balance Sheet'!C7/'Balance Sheet'!B7-1 -> 1.7006617 | D9: ='Balance Sheet'!D7/'Balance Sheet'!C7-1 -> 0.35866537 | E9: 0.25 | F9: 0.2 | G9: 0.18 | H9: 0.15 | I9: 0.12
A10: Servicing rights growth % | C10: ='Balance Sheet'!C11/'Balance Sheet'!B11-1 -> 0.89577157 | D10: ='Balance Sheet'!D11/'Balance Sheet'!C11-1 -> 0.10536992 | E10: 0.06 | F10: 0.06 | G10: 0.06 | H10: 0.06 | I10: 0.06
A12: Income statement drivers
A13: Interest income yield on beginning earning assets % | C13: ='Income Statement'!C5/('Balance Sheet'!B7+'Balance Sheet'!B8+'Balance Sheet'!B9+'Balance Sheet'!B10+'Balance Sheet'!B5) -> 0.1049833 | D13: ='Income Statement'!D5/('Balance Sheet'!C7+'Balance Sheet'!C8+'Balance Sheet'!C9+'Balance Sheet'!C10+'Balance Sheet'!C5) -> 0.10559806 | E13: 0.1 | F13: 0.098 | G13: 0.096 | H13: 0.094 | I13: 0.092 | K13: Beginning-of-year loans + securities + cash (avoids circularity); rate-cut drift
A14: Interest expense rate on beginning funding % | C14: ='Income Statement'!C6/('Balance Sheet'!B20+'Balance Sheet'!B25+'Balance Sheet'!B26) -> 0.045835571 | D14: ='Income Statement'!D6/('Balance Sheet'!C20+'Balance Sheet'!C25+'Balance Sheet'!C26) -> 0.039932825 | E14: 0.039 | F14: 0.038 | G14: 0.037 | H14: 0.036 | I14: 0.035 | K14: Deposits replace higher-cost warehouse funding
A15: Loan origination/sales/servicing income growth % — OUTPUT (driven by Revenue Drivers tab) | C15: ='Income Statement'!C10/'Income Statement'!B10-1 -> -0.32024735 | D15: ='Income Statement'!D10/'Income Statement'!C10-1 -> -0.12644815 | E15: ='Income Statement'!E10/'Income Statement'!D10-1 -> 0.067967238 | F15: ='Income Statement'!F10/'Income Statement'!E10-1 -> 0.12951336 | G15: ='Income Statement'!G10/'Income Statement'!F10-1 -> 0.10506785 | H15: ='Income Statement'!H10/'Income Statement'!G10-1 -> 0.082740157 | I15: ='Income Statement'!I10/'Income Statement'!H10-1 -> 0.068305964
A16: Technology products & solutions growth % | C16: ='Income Statement'!C11/'Income Statement'!B11-1 -> 0.082840492 | D16: ='Income Statement'!D11/'Income Statement'!C11-1 -> 0.02877056 | E16: 0.08 | F16: 0.09 | G16: 0.1 | H16: 0.1 | I16: 0.1
A17: Loan platform fees growth % — OUTPUT (driven by Revenue Drivers tab) | C17: ='Income Statement'!C12/'Income Statement'!B12-1 -> 3.214273 | D17: ='Income Statement'!D12/'Income Statement'!C12-1 -> 3.0669383 | E17: ='Income Statement'!E12/'Income Statement'!D12-1 -> 0.41035681 | F17: ='Income Statement'!F12/'Income Statement'!E12-1 -> 0.27884615 | G17: ='Income Statement'!G12/'Income Statement'!F12-1 -> 0.2096 | H17: ='Income Statement'!H12/'Income Statement'!G12-1 -> 0.15 | I17: ='Income Statement'!I12/'Income Statement'!H12-1 -> 0.10956522 | K17: Capital-light third-party origination platform; FY25 grew 307%
A18: Other noninterest income growth % | C18: ='Income Statement'!C13/'Income Statement'!B13-1 -> 0.99126517 | D18: ='Income Statement'!D13/'Income Statement'!C13-1 -> 0.14262215 | E18: 0.1 | F18: 0.1 | G18: 0.1 | H18: 0.1 | I18: 0.1
A19: Provision % of beginning amortized-cost loans — OUTPUT (driven by Revenue Drivers tab) | C19: ='Income Statement'!C17/'Balance Sheet'!B10 -> 0.037925801 | D19: ='Income Statement'!D17/'Balance Sheet'!C10 -> 0.024324125 | E19: ='Income Statement'!E17/'Balance Sheet'!D10 -> 0.024 | F19: ='Income Statement'!F17/'Balance Sheet'!E10 -> 0.024 | G19: ='Income Statement'!G17/'Balance Sheet'!F10 -> 0.025 | H19: ='Income Statement'!H17/'Balance Sheet'!G10 -> 0.025 | I19: ='Income Statement'!I17/'Balance Sheet'!H10 -> 0.026
A20: Technology & product development % of net revenue | B20: ='Income Statement'!B19/'Income Statement'!B15 -> 0.24091843 | C20: ='Income Statement'!C19/'Income Statement'!C15 -> 0.20628639 | D20: ='Income Statement'!D19/'Income Statement'!D15 -> 0.17942665 | E20: 0.175 | F20: 0.17 | G20: 0.165 | H20: 0.16 | I20: 0.155
A21: Sales & marketing % of net revenue | B21: ='Income Statement'!B20/'Income Statement'!B15 -> 0.33889379 | C21: ='Income Statement'!C20/'Income Statement'!C15 -> 0.29769532 | D21: ='Income Statement'!D20/'Income Statement'!D15 -> 0.30315657 | E21: 0.295 | F21: 0.285 | G21: 0.275 | H21: 0.27 | I21: 0.26
A22: Cost of operations % of net revenue | B22: ='Income Statement'!B21/'Income Statement'!B15 -> 0.17900884 | C22: ='Income Statement'!C21/'Income Statement'!C15 -> 0.17258218 | D22: ='Income Statement'!D21/'Income Statement'!D15 -> 0.16854092 | E22: 0.165 | F22: 0.16 | G22: 0.155 | H22: 0.15 | I22: 0.145
A23: General & administrative % of net revenue | B23: ='Income Statement'!B22/'Income Statement'!B15 -> 0.24072623 | C23: ='Income Statement'!C22/'Income Statement'!C15 -> 0.22434416 | D23: ='Income Statement'!D22/'Income Statement'!D15 -> 0.1949535 | E23: 0.185 | F23: 0.175 | G23: 0.17 | H23: 0.165 | I23: 0.16
A24: Effective tax rate % | D24: ='Income Statement'!D26/'Income Statement'!D25 -> 0.084694128 | E24: 0.25 | F24: 0.25 | G24: 0.25 | H24: 0.25 | I24: 0.25 | K24: FY24 rate not meaningful (large one-time deferred tax valuation allowance release)
A25: Share-based compensation % of net revenue | B25: ='Cash Flow'!B7/'Income Statement'!B15 -> 0.12776399 | C25: ='Cash Flow'!C7/'Income Statement'!C15 -> 0.09202429 | D25: ='Cash Flow'!D7/'Income Statement'!D15 -> 0.072524862 | E25: 0.07 | F25: 0.065 | G25: 0.06 | H25: 0.058 | I25: 0.055
A26: Depreciation & amortization % of net revenue | B26: ='Cash Flow'!B6/'Income Statement'!B15 -> 0.094882723 | C26: ='Cash Flow'!C6/'Income Statement'!C15 -> 0.076078029 | D26: ='Cash Flow'!D6/'Income Statement'!D15 -> 0.064801567 | E26: 0.062 | F26: 0.062 | G26: 0.062 | H26: 0.062 | I26: 0.062
A27: Capex (incl. capitalized software) % of net revenue | B27: =-'Cash Flow'!B17/'Income Statement'!B15 -> 0.057090931 | C27: =-'Cash Flow'!C17/'Income Statement'!C15 -> 0.061168458 | D27: =-'Cash Flow'!D17/'Income Statement'!D15 -> 0.069496927 | E27: 0.068 | F27: 0.068 | G27: 0.068 | H27: 0.068 | I27: 0.068
A28: Diluted share count growth % | C28: ='Income Statement'!C31/'Income Statement'!B31-1 -> 0.16546246 | D28: ='Income Statement'!D31/'Income Statement'!C31-1 -> 0.13653383 | E28: 0.02 | F28: 0.02 | G28: 0.02 | H28: 0.02 | I28: 0.02
A30: Other balance sheet drivers
A31: Other assets % of net revenue | B31: ='Balance Sheet'!B16/'Income Statement'!B15 -> 0.26114984 | C31: ='Balance Sheet'!C16/'Income Statement'!C15 -> 0.64103155 | D31: ='Balance Sheet'!D16/'Income Statement'!D15 -> 0.60249951 | E31: 0.6 | F31: 0.59 | G31: 0.58 | H31: 0.57 | I31: 0.56 | K31: Includes loan platform program receivables; scales with fee business
A32: AP, accruals & other liabilities % of net revenue | B32: ='Balance Sheet'!B23/'Income Statement'!B15 -> 0.2589744 | C32: ='Balance Sheet'!C23/'Income Statement'!C15 -> 0.20820649 | D32: ='Balance Sheet'!D23/'Income Statement'!D15 -> 0.20582428 | E32: 0.205 | F32: 0.205 | G32: 0.205 | H32: 0.205 | I32: 0.205
A33: Debt balance ($000s, input) | B33: ='Balance Sheet'!B25 -> 5233416 | C33: ='Balance Sheet'!C25 -> 3092692 | D33: ='Balance Sheet'!D25 -> 1815162 | E33: 1700000 | F33: 1600000 | G33: 1500000 | H33: 1400000 | I33: 1300000 | K33: Continued paydown of warehouse facilities as deposits fund the balance sheet
A35: Historical columns compute actual ratios from the statement tabs; forecast columns (blue) are inputs.
A36: Restricted cash, goodwill, intangibles, leases and noninterest-bearing deposits held flat in the forecast.

Sheet Revenue Drivers
A1: SoFi Technologies, Inc. — Revenue Drivers (Fintech)
A2: Origination-driven fee & credit build (volumes in $ millions; income in USD thousands) · drives loan fee lines and provision on the Income Statement
B3: FY2023A | C3: FY2024A | D3: FY2025A | E3: FY2026E | F3: FY2027E | G3: FY2028E | H3: FY2029E | I3: FY2030E
A4: Loan originations ($ millions)
A5: Personal loan originations | C5: 17615 | D5: 27495.5 | E5: =D5*(1+E6) -> 32444.69 | F5: =E5*(1+F6) -> 37311.393 | G5: =F5*(1+G6) -> 42161.875 | H5: =G5*(1+H6) -> 46799.681 | I5: =H5*(1+I6) -> 51479.649
A6: Personal origination growth % | D6: =D5/C5-1 -> 0.56091399 | E6: 0.18 | F6: 0.15 | G6: 0.13 | H6: 0.11 | I6: 0.1
A7: Student loan originations | C7: 3780.8 | D7: 5537.9 | E7: =D7*(1+E8) -> 6756.238 | F7: =E7*(1+F8) -> 7972.3608 | G7: =F7*(1+G8) -> 9168.215 | H7: =G7*(1+H8) -> 10360.083 | I7: =H7*(1+I8) -> 11499.692
A8: Student origination growth % | D8: =D7/C7-1 -> 0.46474291 | E8: 0.22 | F8: 0.18 | G8: 0.15 | H8: 0.13 | I8: 0.11
A9: Home loan originations | C9: 1820.2 | D9: 3389 | E9: =D9*(1+E10) -> 4405.7 | F9: =E9*(1+F10) -> 5463.068 | G9: =F9*(1+G10) -> 6501.0509 | H9: =G9*(1+H10) -> 7476.2086 | I9: =H9*(1+I10) -> 8373.3536
A10: Home origination growth % | D10: =D9/C9-1 -> 0.86188331 | E10: 0.3 | F10: 0.24 | G10: 0.19 | H10: 0.15 | I10: 0.12
A11: Total balance-sheet channel originations | C11: =SUM(C5,C7,C9) -> 23216 | D11: =SUM(D5,D7,D9) -> 36422.4 | E11: =SUM(E5,E7,E9) -> 43606.628 | F11: =SUM(F5,F7,F9) -> 50746.822 | G11: =SUM(G5,G7,G9) -> 57831.141 | H11: =SUM(H5,H7,H9) -> 64635.972 | I11: =SUM(I5,I7,I9) -> 71352.695
A12: Loan Platform Business volume (third-party originated) | C12: 2100 | D12: 11000 | E12: =D12*(1+E13) -> 15620 | F12: =E12*(1+F13) -> 20774.6 | G12: =F12*(1+G13) -> 26175.996 | H12: =G12*(1+H13) -> 31411.195 | I12: =H12*(1+I13) -> 36436.986
A13: Loan Platform volume growth % | D13: =D12/C12-1 -> 4.2380952 | E13: 0.42 | F13: 0.33 | G13: 0.26 | H13: 0.2 | I13: 0.16
A15: Monetization (take rates)
A16: % of own originations sold / securitized | E16: 0.35 | F16: 0.35 | G16: 0.35 | H16: 0.35 | I16: 0.35
A17: Gain-on-sale margin on sold volume % | E17: 0.017 | F17: 0.0165 | G17: 0.016 | H17: 0.0155 | I17: 0.015
A18: Origination, sales & servicing income ($000s) | B18: ='Income Statement'!B10 -> 409140 | C18: ='Income Statement'!C10 -> 278114 | D18: ='Income Statement'!D10 -> 242947 | E18: =E11*E16*E17*1000 -> 259459.44 | F18: =F11*F16*F17*1000 -> 293062.9 | G18: =G11*G16*G17*1000 -> 323854.39 | H18: =H11*H16*H17*1000 -> 350650.15 | I18: =I11*I16*I17*1000 -> 374601.65
A19: Loan Platform take rate % | C19: ='Income Statement'!C12/(C12*1000) -> 0.067432381 | D19: ='Income Statement'!D12/(D12*1000) -> 0.052355545 | E19: 0.052 | F19: 0.05 | G19: 0.048 | H19: 0.046 | I19: 0.044
A20: Loan Platform fees ($000s) | B20: ='Income Statement'!B12 -> 33602 | C20: ='Income Statement'!C12 -> 141608 | D20: ='Income Statement'!D12 -> 575911 | E20: =E12*E19*1000 -> 812240 | F20: =F12*F19*1000 -> 1038730 | G20: =G12*G19*1000 -> 1256447.8 | H20: =H12*H19*1000 -> 1444915 | I20: =I12*I19*1000 -> 1603227.4
A22: Credit quality & provision
A23: 90-day delinquency rate — personal loans % | C23: 0.0055 | D23: 0.0055 | E23: 0.0055 | F23: 0.0056 | G23: 0.0057 | H23: 0.0058 | I23: 0.0058
A24: Annualized net charge-off rate — personal loans % | C24: 0.0337 | D24: 0.028 | E24: 0.029 | F24: 0.03 | G24: 0.03 | H24: 0.031 | I24: 0.031
A25: Credit-loss rate on amortized-cost book % | C25: ='Income Statement'!C17/'Balance Sheet'!B10 -> 0.037925801 | D25: ='Income Statement'!D17/'Balance Sheet'!C10 -> 0.024324125 | E25: 0.024 | F25: 0.024 | G25: 0.025 | H25: 0.025 | I25: 0.026
A26: Provision for credit losses ($000s) | B26: ='Income Statement'!B17 -> 54945 | C26: ='Income Statement'!C17 -> 31712 | D26: ='Income Statement'!D17 -> 30319 | E26: ='Balance Sheet'!D10*E25 -> 36401.664 | F26: ='Balance Sheet'!E10*F25 -> 42953.964 | G26: ='Balance Sheet'!F10*G25 -> 51902.706 | H26: ='Balance Sheet'!G10*H25 -> 59688.112 | I26: ='Balance Sheet'!H10*I25 -> 70145.469
A28: Check: origination income vs Income Statement (must be 0) | B28: =B18-'Income Statement'!B10 -> 0 | C28: =C18-'Income Statement'!C10 -> 0 | D28: =D18-'Income Statement'!D10 -> 0 | E28: =E18*'Regional Breakdown'!E42-'Income Statement'!E10 -> 0 | F28: =F18*'Regional Breakdown'!F42-'Income Statement'!F10 -> 0 | G28: =G18*'Regional Breakdown'!G42-'Income Statement'!G10 -> 0 | H28: =H18*'Regional Breakdown'!H42-'Income Statement'!H10 -> 0 | I28: =I18*'Regional Breakdown'!I42-'Income Statement'!I10 -> 0
A29: Check: platform fees vs Income Statement (must be 0) | B29: =B20-'Income Statement'!B12 -> 0 | C29: =C20-'Income Statement'!C12 -> 0 | D29: =D20-'Income Statement'!D12 -> 0 | E29: =E20*'Regional Breakdown'!E42-'Income Statement'!E12 -> 0 | F29: =F20*'Regional Breakdown'!F42-'Income Statement'!F12 -> 0 | G29: =G20*'Regional Breakdown'!G42-'Income Statement'!G12 -> 0 | H29: =H20*'Regional Breakdown'!H42-'Income Statement'!H12 -> 0 | I29: =I20*'Regional Breakdown'!I42-'Income Statement'!I12 -> 0
A30: Check: provision vs Income Statement (must be 0) | B30: =B26-'Income Statement'!B17 -> 0 | C30: =C26-'Income Statement'!C17 -> 0 | D30: =D26-'Income Statement'!D17 -> 0 | E30: =E26-'Income Statement'!E17 -> 0 | F30: =F26-'Income Statement'!F17 -> 0 | G30: =G26-'Income Statement'!G17 -> 0 | H30: =H26-'Income Statement'!H17 -> 0 | I30: =I26-'Income Statement'!I17 -> 0
A32: FY2024–FY2025 origination volumes and credit metrics per SoFi Q4 earnings releases; FY2023 volumes not restated on this basis (left blank).
A33: Delinquency and charge-off rows are leading indicators that inform the credit-loss rate input; most of SoFi's book is carried at fair value, where credit is absorbed through valuation marks — the provision applies to the amortized-cost book.
A34: Interest income is driven separately on the Assumptions tab (yield on earning assets); loan growth assumptions there govern balance-sheet loan balances.

Sheet Regional Breakdown
A1: SoFi Technologies, Inc. — Regional Breakdown & Scenarios
A2: Revenue, growth and customers by region (USD in thousands unless noted) · regional scenario toggle feeds the Income Statement · base = noninterest (fee) revenue
B3: FY2023A | C3: FY2024A | D3: FY2025A | E3: FY2026E | F3: FY2027E | G3: FY2028E | H3: FY2029E | I3: FY2030E
A4: SCENARIO SELECTOR (1 = Standard · 2 = Best Case · 3 = Low Case) | B4: 1 | C4: =CHOOSE(B4,"STANDARD CASE","BEST CASE","LOW CASE") -> STANDARD CASE
A6: REGIONAL MIX (% of noninterest (fee) revenue)
A7: North America mix % | B7: 0.89 | C7: 0.897 | D7: 0.822 | E7: 0.8 | F7: 0.78 | G7: 0.76 | H7: 0.75 | I7: 0.74
A8: Europe mix % | B8: 0.005 | C8: 0.005 | D8: 0.01 | E8: 0.02 | F8: 0.03 | G8: 0.04 | H8: 0.045 | I8: 0.05
A9: Asia Pacific mix % | B9: 0.005 | C9: 0.005 | D9: 0.01 | E9: 0.015 | F9: 0.02 | G9: 0.03 | H9: 0.035 | I9: 0.04
A10: Other / rest of world mix % (balancing) | B10: =1-B7-B8-B9 -> 0.1 | C10: =1-C7-C8-C9 -> 0.093 | D10: =1-D7-D8-D9 -> 0.158 | E10: =1-E7-E8-E9 -> 0.165 | F10: =1-F7-F8-F9 -> 0.17 | G10: =1-G7-G8-G9 -> 0.17 | H10: =1-H7-H8-H9 -> 0.17 | I10: =1-I7-I8-I9 -> 0.17
A12: BASE NONINTEREST (FEE) REVENUE BY REGION ($000s)
A13: Technology products & solutions — base path | B13: ='Income Statement'!B11 -> 323972 | C13: ='Income Statement'!C11 -> 350810 | D13: ='Income Statement'!D11 -> 360903 | E13: =D13*(1+Assumptions!E16) -> 389775.24 | F13: =E13*(1+Assumptions!F16) -> 424855.01 | G13: =F13*(1+Assumptions!G16) -> 467340.51 | H13: =G13*(1+Assumptions!H16) -> 514074.56 | I13: =H13*(1+Assumptions!I16) -> 565482.02
A14: Other noninterest income — base path | B14: ='Income Statement'!B13 -> 94335 | C14: ='Income Statement'!C13 -> 187846 | D14: ='Income Statement'!D13 -> 214637 | E14: =D14*(1+Assumptions!E18) -> 236100.7 | F14: =E14*(1+Assumptions!F18) -> 259710.77 | G14: =F14*(1+Assumptions!G18) -> 285681.85 | H14: =G14*(1+Assumptions!H18) -> 314250.03 | I14: =H14*(1+Assumptions!I18) -> 345675.03
A15: Base noninterest (fee) revenue before regional split | B15: ='Revenue Drivers'!B18+'Revenue Drivers'!B20+B13+B14 -> 861049 | C15: ='Revenue Drivers'!C18+'Revenue Drivers'!C20+C13+C14 -> 958378 | D15: ='Revenue Drivers'!D18+'Revenue Drivers'!D20+D13+D14 -> 1394398 | E15: ='Revenue Drivers'!E18+'Revenue Drivers'!E20+E13+E14 -> 1697575.4 | F15: ='Revenue Drivers'!F18+'Revenue Drivers'!F20+F13+F14 -> 2016358.7 | G15: ='Revenue Drivers'!G18+'Revenue Drivers'!G20+G13+G14 -> 2333324.6 | H15: ='Revenue Drivers'!H18+'Revenue Drivers'!H20+H13+H14 -> 2623889.7 | I15: ='Revenue Drivers'!I18+'Revenue Drivers'!I20+I13+I14 -> 2888986.1
A16: North America — base | B16: =B15*B7 -> 766333.61 | C16: =C15*C7 -> 859665.07 | D16: =D15*D7 -> 1146195.2 | E16: =E15*E7 -> 1358060.3 | F16: =F15*F7 -> 1572759.8 | G16: =G15*G7 -> 1773326.7 | H16: =H15*H7 -> 1967917.3 | I16: =I15*I7 -> 2137849.7
A17: Europe — base | B17: =B15*B8 -> 4305.245 | C17: =C15*C8 -> 4791.89 | D17: =D15*D8 -> 13943.98 | E17: =E15*E8 -> 33951.508 | F17: =F15*F8 -> 60490.76 | G17: =G15*G8 -> 93332.982 | H17: =H15*H8 -> 118075.04 | I17: =I15*I8 -> 144449.31
A18: Asia Pacific — base | B18: =B15*B9 -> 4305.245 | C18: =C15*C9 -> 4791.89 | D18: =D15*D9 -> 13943.98 | E18: =E15*E9 -> 25463.631 | F18: =F15*F9 -> 40327.174 | G18: =G15*G9 -> 69999.737 | H18: =H15*H9 -> 91836.14 | I18: =I15*I9 -> 115559.44
A19: Other / rest of world — base | B19: =B15*B10 -> 86104.9 | C19: =C15*C10 -> 89129.154 | D19: =D15*D10 -> 220314.88 | E19: =E15*E10 -> 280099.94 | F19: =F15*F10 -> 342780.98 | G19: =G15*G10 -> 396665.17 | H19: =H15*H10 -> 446061.25 | I19: =I15*I10 -> 491127.64
A20: Total base (sum of regions) | B20: =SUM(B16:B19) -> 861049 | C20: =SUM(C16:C19) -> 958378 | D20: =SUM(D16:D19) -> 1394398 | E20: =SUM(E16:E19) -> 1697575.4 | F20: =SUM(F16:F19) -> 2016358.7 | G20: =SUM(G16:G19) -> 2333324.6 | H20: =SUM(H16:H19) -> 2623889.7 | I20: =SUM(I16:I19) -> 2888986.1
A22: BASE REGIONAL GROWTH %
A23: North America growth % | C23: =C16/B16-1 -> 0.12178959 | D23: =D16/C16-1 -> 0.33330433 | E23: =E16/D16-1 -> 0.18484212 | F23: =F16/E16-1 -> 0.15809274 | G23: =G16/F16-1 -> 0.12752545 | H23: =H16/G16-1 -> 0.10973197 | I23: =I16/H16-1 -> 0.086351405
A24: Europe growth % | C24: =C17/B17-1 -> 0.11303538 | D24: =D17/C17-1 -> 1.9099124 | E24: =E17/D17-1 -> 1.4348506 | F24: =F17/E17-1 -> 0.78168113 | G24: =G17/F17-1 -> 0.54292956 | H24: =H17/G17-1 -> 0.26509445 | I24: =I17/H17-1 -> 0.2233687
A25: Asia Pacific growth % | C25: =C18/B18-1 -> 0.11303538 | D25: =D18/C18-1 -> 1.9099124 | E25: =E18/D18-1 -> 0.82613792 | F25: =F18/E18-1 -> 0.58371656 | G25: =G18/F18-1 -> 0.73579575 | H25: =H18/G18-1 -> 0.3119498 | I25: =I18/H18-1 -> 0.25832209
A27: SCENARIO GROWTH DELTAS (added to base regional growth)
A28: Best Case — North America | E28: 0.03 | F28: 0.03 | G28: 0.03 | H28: 0.03 | I28: 0.03
A29: Best Case — Europe | E29: 0.08 | F29: 0.08 | G29: 0.08 | H29: 0.08 | I29: 0.08
A30: Best Case — Asia Pacific | E30: 0.12 | F30: 0.12 | G30: 0.12 | H30: 0.12 | I30: 0.12
A31: Low Case — North America | E31: -0.04 | F31: -0.04 | G31: -0.04 | H31: -0.04 | I31: -0.04
A32: Low Case — Europe | E32: -0.08 | F32: -0.08 | G32: -0.08 | H32: -0.08 | I32: -0.08
A33: Low Case — Asia Pacific | E33: -0.1 | F33: -0.1 | G33: -0.1 | H33: -0.1 | I33: -0.1
A35: SCENARIO NONINTEREST (FEE) REVENUE BY REGION ($000s)
A36: North America — scenario | B36: =B16 -> 766333.61 | C36: =C16 -> 859665.07 | D36: =D16 -> 1146195.2 | E36: =D36*(1+E23+CHOOSE($B$4,0,E28,E31)) -> 1358060.3 | F36: =E36*(1+F23+CHOOSE($B$4,0,F28,F31)) -> 1572759.8 | G36: =F36*(1+G23+CHOOSE($B$4,0,G28,G31)) -> 1773326.7 | H36: =G36*(1+H23+CHOOSE($B$4,0,H28,H31)) -> 1967917.3 | I36: =H36*(1+I23+CHOOSE($B$4,0,I28,I31)) -> 2137849.7
A37: Europe — scenario | B37: =B17 -> 4305.245 | C37: =C17 -> 4791.89 | D37: =D17 -> 13943.98 | E37: =D37*(1+E24+CHOOSE($B$4,0,E29,E32)) -> 33951.508 | F37: =E37*(1+F24+CHOOSE($B$4,0,F29,F32)) -> 60490.76 | G37: =F37*(1+G24+CHOOSE($B$4,0,G29,G32)) -> 93332.982 | H37: =G37*(1+H24+CHOOSE($B$4,0,H29,H32)) -> 118075.04 | I37: =H37*(1+I24+CHOOSE($B$4,0,I29,I32)) -> 144449.31
A38: Asia Pacific — scenario | B38: =B18 -> 4305.245 | C38: =C18 -> 4791.89 | D38: =D18 -> 13943.98 | E38: =D38*(1+E25+CHOOSE($B$4,0,E30,E33)) -> 25463.631 | F38: =E38*(1+F25+CHOOSE($B$4,0,F30,F33)) -> 40327.174 | G38: =F38*(1+G25+CHOOSE($B$4,0,G30,G33)) -> 69999.737 | H38: =G38*(1+H25+CHOOSE($B$4,0,H30,H33)) -> 91836.14 | I38: =H38*(1+I25+CHOOSE($B$4,0,I30,I33)) -> 115559.44
A39: Other / rest of world — scenario (no delta) | B39: =B19 -> 86104.9 | C39: =C19 -> 89129.154 | D39: =D19 -> 220314.88 | E39: =E19 -> 280099.94 | F39: =F19 -> 342780.98 | G39: =G19 -> 396665.17 | H39: =H19 -> 446061.25 | I39: =I19 -> 491127.64
A40: TOTAL — SCENARIO ($000s) | B40: =SUM(B36:B39) -> 861049 | C40: =SUM(C36:C39) -> 958378 | D40: =SUM(D36:D39) -> 1394398 | E40: =SUM(E36:E39) -> 1697575.4 | F40: =SUM(F36:F39) -> 2016358.7 | G40: =SUM(G36:G39) -> 2333324.6 | H40: =SUM(H36:H39) -> 2623889.7 | I40: =SUM(I36:I39) -> 2888986.1
A41: Scenario total growth % | C41: =C40/B40-1 -> 0.11303538 | D41: =D40/C40-1 -> 0.45495619 | E41: =E40/D40-1 -> 0.21742528 | F41: =F40/E40-1 -> 0.18778742 | G41: =G40/F40-1 -> 0.15719717 | H41: =H40/G40-1 -> 0.1245284 | I41: =I40/H40-1 -> 0.10103183
A42: Scenario scaling factor (× base) | B42: =B40/B20 -> 1 | C42: =C40/C20 -> 1 | D42: =D40/D20 -> 1 | E42: =E40/E20 -> 1 | F42: =F40/F20 -> 1 | G42: =G40/G20 -> 1 | H42: =H40/H20 -> 1 | I42: =I40/I20 -> 1
A43: Scenario revenue delta vs base ($000s) | B43: =B40-B20 -> 0 | C43: =C40-C20 -> 0 | D43: =D40-D20 -> 0 | E43: =E40-E20 -> 0 | F43: =F40-F20 -> 0 | G43: =G40-G20 -> 0 | H43: =H40-H20 -> 0 | I43: =I40-I20 -> 0
A45: SCENARIO IMPACT DASHBOARD (flips with the selector)
A46: Total net revenue — scenario ($000s) | B46: ='Income Statement'!B15 -> 2122789 | C46: ='Income Statement'!C15 -> 2674859 | D46: ='Income Statement'!D15 -> 3613354 | E46: ='Income Statement'!E15 -> 4722869.3 | F46: ='Income Statement'!F15 -> 5655819.2 | G46: ='Income Statement'!G15 -> 6663574.5 | H46: ='Income Statement'!H15 -> 7668410.4 | I46: ='Income Statement'!I15 -> 8664907.9
...

Sheet Income Statement
A1: SoFi Technologies, Inc. — Statement of Operations
A2: (USD in thousands, except per-share amounts) · FY2023A–FY2025A per SEC filings · FY2026E–FY2030E forecast
B3: FY2023A | C3: FY2024A | D3: FY2025A | E3: FY2026E | F3: FY2027E | G3: FY2028E | H3: FY2029E | I3: FY2030E
A4: Interest income and expense
A5: Total interest income | B5: 2051067 | C5: 2807817 | D5: 3375199 | E5: =('Balance Sheet'!D7+'Balance Sheet'!D8+'Balance Sheet'!D9+'Balance Sheet'!D10+'Balance Sheet'!D5)*Assumptions!E13 -> 4554212.2 | F5: =('Balance Sheet'!E7+'Balance Sheet'!E8+'Balance Sheet'!E9+'Balance Sheet'!E10+'Balance Sheet'!E5)*Assumptions!F13 -> 5522601 | G5: =('Balance Sheet'!F7+'Balance Sheet'!F8+'Balance Sheet'!F9+'Balance Sheet'!F10+'Balance Sheet'!F5)*Assumptions!G13 -> 6585093.7 | H5: =('Balance Sheet'!G7+'Balance Sheet'!G8+'Balance Sheet'!G9+'Balance Sheet'!G10+'Balance Sheet'!G5)*Assumptions!H13 -> 7662079.3 | I5: =('Balance Sheet'!H7+'Balance Sheet'!H8+'Balance Sheet'!H9+'Balance Sheet'!H10+'Balance Sheet'!H5)*Assumptions!I13 -> 8740966.7 | K5: Source: SOFI Q4 FY2025 earnings release and FY2025 10-K (SEC); provision presented below total net revenue per current presentation
A6: Total interest expense | B6: 789327 | C6: 1091336 | D6: 1156243 | E6: =('Balance Sheet'!D20+'Balance Sheet'!D25+'Balance Sheet'!D26)*Assumptions!E14 -> 1528918.2 | F6: =('Balance Sheet'!E20+'Balance Sheet'!E25+'Balance Sheet'!E26)*Assumptions!F14 -> 1883140.5 | G6: =('Balance Sheet'!F20+'Balance Sheet'!F25+'Balance Sheet'!F26)*Assumptions!G14 -> 2254843.7 | H6: =('Balance Sheet'!G20+'Balance Sheet'!G25+'Balance Sheet'!G26)*Assumptions!H14 -> 2617558.6 | I6: =('Balance Sheet'!H20+'Balance Sheet'!H25+'Balance Sheet'!H26)*Assumptions!I14 -> 2965044.9
A7: Net interest income | B7: =B5-B6 -> 1261740 | C7: =C5-C6 -> 1716481 | D7: =D5-D6 -> 2218956 | E7: =E5-E6 -> 3025294 | F7: =F5-F6 -> 3639460.6 | G7: =G5-G6 -> 4330250 | H7: =H5-H6 -> 5044520.7 | I7: =I5-I6 -> 5775921.8
A9: Noninterest income
A10: Loan origination, sales, securitizations and servicing | B10: 409140 | C10: 278114 | D10: 242947 | E10: ='Revenue Drivers'!E18*'Regional Breakdown'!E42 -> 259459.44 | F10: ='Revenue Drivers'!F18*'Regional Breakdown'!F42 -> 293062.9 | G10: ='Revenue Drivers'!G18*'Regional Breakdown'!G42 -> 323854.39 | H10: ='Revenue Drivers'!H18*'Regional Breakdown'!H42 -> 350650.15 | I10: ='Revenue Drivers'!I18*'Regional Breakdown'!I42 -> 374601.65
A11: Technology products and solutions | B11: 323972 | C11: 350810 | D11: 360903 | E11: ='Regional Breakdown'!E13*'Regional Breakdown'!E42 -> 389775.24 | F11: ='Regional Breakdown'!F13*'Regional Breakdown'!F42 -> 424855.01 | G11: ='Regional Breakdown'!G13*'Regional Breakdown'!G42 -> 467340.51 | H11: ='Regional Breakdown'!H13*'Regional Breakdown'!H42 -> 514074.56 | I11: ='Regional Breakdown'!I13*'Regional Breakdown'!I42 -> 565482.02
A12: Loan platform fees | B12: 33602 | C12: 141608 | D12: 575911 | E12: ='Revenue Drivers'!E20*'Regional Breakdown'!E42 -> 812240 | F12: ='Revenue Drivers'!F20*'Regional Breakdown'!F42 -> 1038730 | G12: ='Revenue Drivers'!G20*'Regional Breakdown'!G42 -> 1256447.8 | H12: ='Revenue Drivers'!H20*'Regional Breakdown'!H42 -> 1444915 | I12: ='Revenue Drivers'!I20*'Regional Breakdown'!I42 -> 1603227.4
A13: Other noninterest income | B13: 94335 | C13: 187846 | D13: 214637 | E13: ='Regional Breakdown'!E14*'Regional Breakdown'!E42 -> 236100.7 | F13: ='Regional Breakdown'!F14*'Regional Breakdown'!F42 -> 259710.77 | G13: ='Regional Breakdown'!G14*'Regional Breakdown'!G42 -> 285681.85 | H13: ='Regional Breakdown'!H14*'Regional Breakdown'!H42 -> 314250.03 | I13: ='Regional Breakdown'!I14*'Regional Breakdown'!I42 -> 345675.03
A14: Total noninterest income | B14: =SUM(B10:B13) -> 861049 | C14: =SUM(C10:C13) -> 958378 | D14: =SUM(D10:D13) -> 1394398 | E14: =SUM(E10:E13) -> 1697575.4 | F14: =SUM(F10:F13) -> 2016358.7 | G14: =SUM(G10:G13) -> 2333324.6 | H14: =SUM(H10:H13) -> 2623889.7 | I14: =SUM(I10:I13) -> 2888986.1
A15: Total net revenue | B15: =B7+B14 -> 2122789 | C15: =C7+C14 -> 2674859 | D15: =D7+D14 -> 3613354 | E15: =E7+E14 -> 4722869.3 | F15: =F7+F14 -> 5655819.2 | G15: =G7+G14 -> 6663574.5 | H15: =H7+H14 -> 7668410.4 | I15: =I7+I14 -> 8664907.9
A17: Provision for credit losses | B17: 54945 | C17: 31712 | D17: 30319 | E17: ='Revenue Drivers'!E26 -> 36401.664 | F17: ='Revenue Drivers'!F26 -> 42953.964 | G17: ='Revenue Drivers'!G26 -> 51902.706 | H17: ='Revenue Drivers'!H26 -> 59688.112 | I17: ='Revenue Drivers'!I26 -> 70145.469
A18: Noninterest expense
A19: Technology and product development | B19: 511419 | C19: 551787 | D19: 648332 | E19: =E15*Assumptions!E20 -> 826502.13 | F19: =F15*Assumptions!F20 -> 961489.27 | G19: =G15*Assumptions!G20 -> 1099489.8 | H19: =H15*Assumptions!H20 -> 1226945.7 | I19: =I15*Assumptions!I20 -> 1343060.7
A20: Sales and marketing | B20: 719400 | C20: 796293 | D20: 1095412 | E20: =E15*Assumptions!E21 -> 1393246.5 | F20: =F15*Assumptions!F21 -> 1611908.5 | G20: =G15*Assumptions!G21 -> 1832483 | H20: =H15*Assumptions!H21 -> 2070470.8 | I20: =I15*Assumptions!I21 -> 2252876.1
A21: Cost of operations | B21: 379998 | C21: 461633 | D21: 608998 | E21: =E15*Assumptions!E22 -> 779273.44 | F21: =F15*Assumptions!F22 -> 904931.08 | G21: =G15*Assumptions!G22 -> 1032854.1 | H21: =H15*Assumptions!H22 -> 1150261.6 | I21: =I15*Assumptions!I22 -> 1256411.7
A22: General and administrative | B22: 511011 | C22: 600089 | D22: 704436 | E22: =E15*Assumptions!E23 -> 873730.83 | F22: =F15*Assumptions!F23 -> 989768.37 | G22: =G15*Assumptions!G23 -> 1132807.7 | H22: =H15*Assumptions!H23 -> 1265287.7 | I22: =I15*Assumptions!I23 -> 1386385.3
A23: Goodwill impairment | B23: 247174 | C23: 0 | D23: 0 | E23: 0 | F23: 0 | G23: 0 | H23: 0 | I23: 0
A24: Total noninterest expense | B24: =SUM(B19:B23) -> 2369002 | C24: =SUM(C19:C23) -> 2409802 | D24: =SUM(D19:D23) -> 3057178 | E24: =SUM(E19:E23) -> 3872752.8 | F24: =SUM(F19:F23) -> 4468097.2 | G24: =SUM(G19:G23) -> 5097634.5 | H24: =SUM(H19:H23) -> 5712965.7 | I24: =SUM(I19:I23) -> 6238733.7
A25: Income (loss) before income taxes | B25: =B15-B17-B24 -> -301158 | C25: =C15-C17-C24 -> 233345 | D25: =D15-D17-D24 -> 525857 | E25: =E15-E17-E24 -> 813714.82 | F25: =F15-F17-F24 -> 1144768.1 | G25: =G15-G17-G24 -> 1514037.3 | H25: =H15-H17-H24 -> 1895756.5 | I25: =I15-I17-I24 -> 2356028.8
A26: Income tax expense (benefit) | B26: -416 | C26: -265320 | D26: 44537 | E26: =E25*Assumptions!E24 -> 203428.7 | F26: =F25*Assumptions!F24 -> 286192.02 | G26: =G25*Assumptions!G24 -> 378509.33 | H26: =H25*Assumptions!H24 -> 473939.13 | I26: =I25*Assumptions!I24 -> 589007.19 | K26: FY2024 includes a large one-time deferred tax benefit (valuation allowance release)
A27: Net income (loss) | B27: =B25-B26 -> -300742 | C27: =C25-C26 -> 498665 | D27: =D25-D26 -> 481320 | E27: =E25-E26 -> 610286.11 | F27: =F25-F26 -> 858576.06 | G27: =G25-G26 -> 1135528 | H27: =H25-H26 -> 1421817.4 | I27: =I25-I26 -> 1767021.6
A28: Preferred dividends and redemption adjustments | B28: -40425 | C28: -19529 | D28: 0 | E28: 0 | F28: 0 | G28: 0 | H28: 0 | I28: 0
A29: Net income (loss) attributable to common stockholders | B29: =B27+B28 -> -341167 | C29: =C27+C28 -> 479136 | D29: =D27+D28 -> 481320 | E29: =E27+E28 -> 610286.11 | F29: =F27+F28 -> 858576.06 | G29: =G27+G28 -> 1135528 | H29: =H27+H28 -> 1421817.4 | I29: =I27+I28 -> 1767021.6
A31: Weighted-average diluted shares outstanding | B31: 945024 | C31: 1101390 | D31: 1251767 | E31: =D31*(1+Assumptions!E28) -> 1276802.3 | F31: =E31*(1+Assumptions!F28) -> 1302338.4 | G31: =F31*(1+Assumptions!G28) -> 1328385.2 | H31: =G31*(1+Assumptions!H28) -> 1354952.9 | I31: =H31*(1+Assumptions!I28) -> 1382051.9
A32: Diluted EPS ($) | B32: -0.36 | C32: 0.39 | D32: 0.39 | E32: =E29/E31 -> 0.4779801 | F32: =F29/F31 -> 0.65925728 | G32: =G29/G31 -> 0.85481833 | H32: =H29/H31 -> 1.0493482 | I32: =I29/I31 -> 1.2785493 | K32: Historical diluted EPS as reported (reflects dilutive convertible note adjustments); forecast = NI to common / diluted shares
A34: Memo: share-based compensation expense | B34: 271216 | C34: 246152 | D34: 262058 | E34: =E15*Assumptions!E25 -> 330600.85 | F34: =F15*Assumptions!F25 -> 367628.25 | G34: =G15*Assumptions!G25 -> 399814.47 | H34: =H15*Assumptions!H25 -> 444767.8 | I34: =I15*Assumptions!I25 -> 476569.94
A35: Memo: depreciation and amortization | B35: 201416 | C35: 203498 | D35: 234151 | E35: =E15*Assumptions!E26 -> 292817.9 | F35: =F15*Assumptions!F26 -> 350660.79 | G35: =G15*Assumptions!G26 -> 413141.62 | H35: =H15*Assumptions!H26 -> 475441.44 | I35: =I15*Assumptions!I26 -> 537224.29

Sheet Balance Sheet
A1: SoFi Technologies, Inc. — Balance Sheet
A2: (USD in thousands, except per-share amounts) · FY2023A–FY2025A per SEC filings · FY2026E–FY2030E forecast
B3: FY2023A | C3: FY2024A | D3: FY2025A | E3: FY2026E | F3: FY2027E | G3: FY2028E | H3: FY2029E | I3: FY2030E
A4: Assets
A5: Cash and cash equivalents | B5: 3085020 | C5: 2538293 | D5: 4929452 | E5: ='Cash Flow'!E33 -> 6153664.3 | F5: ='Cash Flow'!F33 -> 8087990.3 | G5: ='Cash Flow'!G33 -> 10703156 | H5: ='Cash Flow'!H33 -> 13574308 | I5: ='Cash Flow'!I33 -> 17142322
A6: Restricted cash and equivalents | B6: 530558 | C6: 171067 | D6: 427321 | E6: =D6 -> 427321 | F6: =E6 -> 427321 | G6: =F6 -> 427321 | H6: =G6 -> 427321 | I6: =H6 -> 427321
A7: Investment securities | B7: 701935 | C7: 1895689 | D7: 2575607 | E7: =D7*(1+Assumptions!E9) -> 3219508.8 | F7: =E7*(1+Assumptions!F9) -> 3863410.5 | G7: =F7*(1+Assumptions!G9) -> 4558824.4 | H7: =G7*(1+Assumptions!H9) -> 5242648 | I7: =H7*(1+Assumptions!I9) -> 5871765.8
A8: Loans held for sale, at fair value | B8: 15396771 | C8: 17684892 | D8: 22862749 | E8: =D8*(1+Assumptions!E6) -> 27435299 | F8: =E8*(1+Assumptions!F6) -> 32373653 | G8: =F8*(1+Assumptions!G6) -> 37229700 | H8: =G8*(1+Assumptions!H6) -> 42069562 | I8: =H8*(1+Assumptions!I6) -> 47117909
A9: Loans held for investment, at fair value | B9: 6725484 | C9: 8597368 | D9: 13657578 | E9: =D9*(1+Assumptions!E7) -> 17754851 | F9: =E9*(1+Assumptions!F7) -> 22193564 | G9: =F9*(1+Assumptions!G7) -> 26632277 | H9: =G9*(1+Assumptions!H7) -> 31426087 | I9: =H9*(1+Assumptions!I7) -> 36140000
A10: Loans held for investment, at amortized cost (net) | B10: 836159 | C10: 1246458 | D10: 1516736 | E10: =D10*(1+Assumptions!E8) -> 1789748.5 | F10: =E10*(1+Assumptions!F8) -> 2076108.2 | G10: =F10*(1+Assumptions!G8) -> 2387524.5 | H10: =G10*(1+Assumptions!H8) -> 2697902.7 | I10: =H10*(1+Assumptions!I8) -> 3021651
A11: Servicing rights | B11: 180469 | C11: 342128 | D11: 378178 | E11: =D11*(1+Assumptions!E10) -> 400868.68 | F11: =E11*(1+Assumptions!F10) -> 424920.8 | G11: =F11*(1+Assumptions!G10) -> 450416.05 | H11: =G11*(1+Assumptions!H10) -> 477441.01 | I11: =H11*(1+Assumptions!I10) -> 506087.47
A12: Property, equipment and software | B12: 216908 | C12: 287869 | D12: 416448 | E12: =D12-'Cash Flow'!E17-'Cash Flow'!E6 -> 444785.22 | F12: =E12-'Cash Flow'!F17-'Cash Flow'!F6 -> 478720.13 | G12: =F12-'Cash Flow'!G17-'Cash Flow'!G6 -> 518701.58 | H12: =G12-'Cash Flow'!H17-'Cash Flow'!H6 -> 564712.04 | I12: =H12-'Cash Flow'!I17-'Cash Flow'!I6 -> 616701.49
A13: Goodwill | B13: 1393505 | C13: 1393505 | D13: 1393505 | E13: =D13 -> 1393505 | F13: =E13 -> 1393505 | G13: =F13 -> 1393505 | H13: =G13 -> 1393505 | I13: =H13 -> 1393505
A14: Intangible assets | B14: 364048 | C14: 297794 | D14: 231919 | E14: =D14 -> 231919 | F14: =E14 -> 231919 | G14: =F14 -> 231919 | H14: =G14 -> 231919 | I14: =H14 -> 231919
A15: Operating lease right-of-use assets | B15: 89635 | C15: 81219 | D15: 93941 | E15: =D15 -> 93941 | F15: =E15 -> 93941 | G15: =F15 -> 93941 | H15: =G15 -> 93941 | I15: =H15 -> 93941
A16: Other assets | B16: 554366 | C16: 1714669 | D16: 2177044 | E16: ='Income Statement'!E15*Assumptions!E31 -> 2833721.6 | F16: ='Income Statement'!F15*Assumptions!F31 -> 3336933.4 | G16: ='Income Statement'!G15*Assumptions!G31 -> 3864873.2 | H16: ='Income Statement'!H15*Assumptions!H31 -> 4370993.9 | I16: ='Income Statement'!I15*Assumptions!I31 -> 4852348.4 | K16: Includes loan platform program receivables — grew with the capital-light fee business
A17: Total assets | B17: =SUM(B5:B16) -> 30074858 | C17: =SUM(C5:C16) -> 36250951 | D17: =SUM(D5:D16) -> 50660478 | E17: =SUM(E5:E16) -> 62179133 | F17: =SUM(F5:F16) -> 74981986 | G17: =SUM(G5:G16) -> 88492159 | H17: =SUM(H5:H16) -> 1.0257034e+08 | I17: =SUM(I5:I16) -> 1.1741547e+08
A19: Liabilities
A20: Interest-bearing deposits | B20: 18568993 | C20: 25861400 | D20: 37387350 | E20: =D20*(1+Assumptions!E5) -> 47855808 | F20: =E20*(1+Assumptions!F5) -> 59341202 | G20: =F20*(1+Assumptions!G5) -> 71209442 | H20: =G20*(1+Assumptions!H5) -> 83315047 | I20: =H20*(1+Assumptions!I5) -> 95812305
A21: Noninterest-bearing deposits | B21: 51670 | C21: 116804 | D21: 118045 | E21: =D21 -> 118045 | F21: =E21 -> 118045 | G21: =F21 -> 118045 | H21: =G21 -> 118045 | I21: =H21 -> 118045
A22: Total deposits | B22: =B20+B21 -> 18620663 | C22: =C20+C21 -> 25978204 | D22: =D20+D21 -> 37505395 | E22: =E20+E21 -> 47973853 | F22: =F20+F21 -> 59459247 | G22: =G20+G21 -> 71327487 | H22: =H20+H21 -> 83433092 | I22: =I20+I21 -> 95930350
A23: Accounts payable, accruals and other liabilities | B23: 549748 | C23: 556923 | D23: 743716 | E23: ='Income Statement'!E15*Assumptions!E32 -> 968188.21 | F23: ='Income Statement'!F15*Assumptions!F32 -> 1159442.9 | G23: ='Income Statement'!G15*Assumptions!G32 -> 1366032.8 | H23: ='Income Statement'!H15*Assumptions!H32 -> 1572024.1 | I23: ='Income Statement'!I15*Assumptions!I32 -> 1776306.1
A24: Operating lease liabilities | B24: 108649 | C24: 97389 | D24: 106190 | E24: =D24 -> 106190 | F24: =E24 -> 106190 | G24: =F24 -> 106190 | H24: =G24 -> 106190 | I24: =H24 -> 106190
A25: Debt (incl. warehouse facilities) | B25: 5233416 | C25: 3092692 | D25: 1815162 | E25: =Assumptions!E33 -> 1700000 | F25: =Assumptions!F33 -> 1600000 | G25: =Assumptions!G33 -> 1500000 | H25: =Assumptions!H33 -> 1400000 | I25: =Assumptions!I33 -> 1300000
A26: Residual interests classified as debt | B26: 7396 | C26: 609 | D26: 520 | E26: =D26 -> 520 | F26: =E26 -> 520 | G26: =F26 -> 520 | H26: =G26 -> 520 | I26: =H26 -> 520
A27: Total liabilities | B27: =B22+SUM(B23:B26) -> 24519872 | C27: =C22+SUM(C23:C26) -> 29725817 | D27: =D22+SUM(D23:D26) -> 40170983 | E27: =E22+SUM(E23:E26) -> 50748751 | F27: =F22+SUM(F23:F26) -> 62325400 | G27: =G22+SUM(G23:G26) -> 74300230 | H27: =H22+SUM(H23:H26) -> 86511827 | I27: =I22+SUM(I23:I26) -> 99113366
A29: Redeemable preferred stock (temporary equity) | B29: 320374 | C29: 0 | D29: 0 | E29: 0 | F29: 0 | G29: 0 | H29: 0 | I29: 0
A30: Permanent equity
A31: Common stock | B31: 97 | C31: 109 | D31: 126 | E31: =D31 -> 126 | F31: =E31 -> 126 | G31: =F31 -> 126 | H31: =G31 -> 126 | I31: =H31 -> 126
A32: Additional paid-in capital | B32: 7039987 | C32: 7838988 | D32: 11302668 | E32: =D32+'Cash Flow'!E7+'Cash Flow'!E24 -> 11633269 | F32: =E32+'Cash Flow'!F7+'Cash Flow'!F24 -> 12000897 | G32: =F32+'Cash Flow'!G7+'Cash Flow'!G24 -> 12400712 | H32: =G32+'Cash Flow'!H7+'Cash Flow'!H24 -> 12845479 | I32: =H32+'Cash Flow'!I7+'Cash Flow'!I24 -> 13322049
A33: Accumulated other comprehensive income (loss) | B33: -1209 | C33: -8365 | D33: 10979 | E33: =D33 -> 10979 | F33: =E33 -> 10979 | G33: =F33 -> 10979 | H33: =G33 -> 10979 | I33: =H33 -> 10979
A34: Accumulated deficit | B34: -1804263 | C34: -1305598 | D34: -824278 | E34: =D34+'Income Statement'!E29 -> -213991.89 | F34: =E34+'Income Statement'!F29 -> 644584.17 | G34: =F34+'Income Statement'!G29 -> 1780112.1 | H34: =G34+'Income Statement'!H29 -> 3201929.6 | I34: =H34+'Income Statement'!I29 -> 4968951.1
A35: Total permanent equity | B35: =SUM(B31:B34) -> 5234612 | C35: =SUM(C31:C34) -> 6525134 | D35: =SUM(D31:D34) -> 10489495 | E35: =SUM(E31:E34) -> 11430382 | F35: =SUM(F31:F34) -> 12656586 | G35: =SUM(G31:G34) -> 14191929 | H35: =SUM(H31:H34) -> 16058514 | I35: =SUM(I31:I34) -> 18302105
A36: Total liabilities, temporary equity and permanent equity | B36: =B27+B29+B35 -> 30074858 | C36: =C27+C29+C35 -> 36250951 | D36: =D27+D29+D35 -> 50660478 | E36: =E27+E29+E35 -> 62179133 | F36: =F27+F29+F35 -> 74981986 | G36: =G27+G29+G35 -> 88492159 | H36: =H27+H29+H35 -> 1.0257034e+08 | I36: =I27+I29+I35 -> 1.1741547e+08
A38: Balance check (assets − liabilities & equity) | B38: =B17-B36 -> 0 | C38: =C17-C36 -> 0 | D38: =D17-D36 -> 0 | E38: =E17-E36 -> 0 | F38: =F17-F36 -> 0 | G38: =G17-G36 -> 0 | H38: =H17-H36 -> 0 | I38: =I17-I36 -> 0 | K38: Must be zero in every period

Sheet Cash Flow
A1: SoFi Technologies, Inc. — Statement of Cash Flows
A2: (USD in thousands, except per-share amounts) · FY2023A–FY2025A per SEC filings · FY2026E–FY2030E forecast
B3: FY2023A | C3: FY2024A | D3: FY2025A | E3: FY2026E | F3: FY2027E | G3: FY2028E | H3: FY2029E | I3: FY2030E
A4: Operating activities
A5: Net income (loss) | B5: -300742 | C5: 498665 | D5: 481320 | E5: ='Income Statement'!E27 -> 610286.11 | F5: ='Income Statement'!F27 -> 858576.06 | G5: ='Income Statement'!G27 -> 1135528 | H5: ='Income Statement'!H27 -> 1421817.4 | I5: ='Income Statement'!I27 -> 1767021.6
A6: Depreciation and amortization | B6: 201416 | C6: 203498 | D6: 234151 | E6: ='Income Statement'!E35 -> 292817.9 | F6: ='Income Statement'!F35 -> 350660.79 | G6: ='Income Statement'!G35 -> 413141.62 | H6: ='Income Statement'!H35 -> 475441.44 | I6: ='Income Statement'!I35 -> 537224.29
A7: Share-based compensation | B7: 271216 | C7: 246152 | D7: 262058 | E7: ='Income Statement'!E34 -> 330600.85 | F7: ='Income Statement'!F34 -> 367628.25 | G7: ='Income Statement'!G34 -> 399814.47 | H7: ='Income Statement'!H34 -> 444767.8 | I7: ='Income Statement'!I34 -> 476569.94
A8: Net change in loans held for sale | B8: -7568079 | C8: -991697 | D8: -4396862 | E8: =-('Balance Sheet'!E8-'Balance Sheet'!D8) -> -4572549.8 | F8: =-('Balance Sheet'!F8-'Balance Sheet'!E8) -> -4938353.8 | G8: =-('Balance Sheet'!G8-'Balance Sheet'!F8) -> -4856047.9 | H8: =-('Balance Sheet'!H8-'Balance Sheet'!G8) -> -4839861.1 | I8: =-('Balance Sheet'!I8-'Balance Sheet'!H8) -> -5048347.4 | K8: GAAP presents held-for-sale loan flows within operating activities
A9: Net change in servicing rights | B9: -31604 | C9: -161659 | D9: -36050 | E9: =-('Balance Sheet'!E11-'Balance Sheet'!D11) -> -22690.68 | F9: =-('Balance Sheet'!F11-'Balance Sheet'!E11) -> -24052.121 | G9: =-('Balance Sheet'!G11-'Balance Sheet'!F11) -> -25495.248 | H9: =-('Balance Sheet'!H11-'Balance Sheet'!G11) -> -27024.963 | I9: =-('Balance Sheet'!I11-'Balance Sheet'!H11) -> -28646.461
A10: Net change in other assets and other liabilities | B10: 36582 | C10: -434898 | D10: 39790 | E10: =-('Balance Sheet'!E16-'Balance Sheet'!D16)+('Balance Sheet'!E23-'Balance Sheet'!D23) -> -432205.38 | F10: =-('Balance Sheet'!F16-'Balance Sheet'!E16)+('Balance Sheet'!F23-'Balance Sheet'!E23) -> -311957.02 | G10: =-('Balance Sheet'!G16-'Balance Sheet'!F16)+('Balance Sheet'!G23-'Balance Sheet'!F23) -> -321350.04 | H10: =-('Balance Sheet'!H16-'Balance Sheet'!G16)+('Balance Sheet'!H23-'Balance Sheet'!G23) -> -300129.34 | I10: =-('Balance Sheet'!I16-'Balance Sheet'!H16)+('Balance Sheet'!I23-'Balance Sheet'!H23) -> -277072.53
A11: Other operating adjustments, net | B11: 164072 | C11: -479868 | D11: -326865 | E11: 0 | F11: 0 | G11: 0 | H11: 0 | I11: 0 | K11: Historical: provision, fair-value changes, deferred taxes, goodwill impairment and other, per 10-K
A12: Net cash provided by (used in) operating activities | B12: =SUM(B5:B11) -> -7227139 | C12: =SUM(C5:C11) -> -1119807 | D12: =SUM(D5:D11) -> -3742458 | E12: =SUM(E5:E11) -> -3793741 | F12: =SUM(F5:F11) -> -3697497.8 | G12: =SUM(G5:G11) -> -3254409.1 | H12: =SUM(H5:H11) -> -2824988.7 | I12: =SUM(I5:I11) -> -2573250.6
A14: Investing activities
A15: Net (purchases) of investment securities | B15: -381045 | C15: -1197204 | D15: -596725 | E15: =-('Balance Sheet'!E7-'Balance Sheet'!D7) -> -643901.75 | F15: =-('Balance Sheet'!F7-'Balance Sheet'!E7) -> -643901.75 | G15: =-('Balance Sheet'!G7-'Balance Sheet'!F7) -> -695413.89 | H15: =-('Balance Sheet'!H7-'Balance Sheet'!G7) -> -683823.66 | I15: =-('Balance Sheet'!I7-'Balance Sheet'!H7) -> -629117.77
A16: Net (originations) of loans held for investment | B16: -1362418 | C16: -3505792 | D16: -5889488 | E16: =-('Balance Sheet'!E9-'Balance Sheet'!D9)-('Balance Sheet'!E10-'Balance Sheet'!D10) -> -4370285.9 | F16: =-('Balance Sheet'!F9-'Balance Sheet'!E9)-('Balance Sheet'!F10-'Balance Sheet'!E10) -> -4725072.6 | G16: =-('Balance Sheet'!G9-'Balance Sheet'!F9)-('Balance Sheet'!G10-'Balance Sheet'!F10) -> -4750129.1 | H16: =-('Balance Sheet'!H9-'Balance Sheet'!G9)-('Balance Sheet'!H10-'Balance Sheet'!G10) -> -5104188.1 | I16: =-('Balance Sheet'!I9-'Balance Sheet'!H9)-('Balance Sheet'!I10-'Balance Sheet'!H10) -> -5037661.4
A17: Purchases of property, equipment and software | B17: -121192 | C17: -163617 | D17: -251117 | E17: =-'Income Statement'!E15*Assumptions!E27 -> -321155.11 | F17: =-'Income Statement'!F15*Assumptions!F27 -> -384595.71 | G17: =-'Income Statement'!G15*Assumptions!G27 -> -453123.07 | H17: =-'Income Statement'!H15*Assumptions!H27 -> -521451.91 | I17: =-'Income Statement'!I15*Assumptions!I27 -> -589213.74
A18: Other investing activities | B18: -25209 | C18: 45623 | D18: 18223 | E18: 0 | F18: 0 | G18: 0 | H18: 0 | I18: 0
A19: Net cash used in investing activities | B19: =SUM(B15:B18) -> -1889864 | C19: =SUM(C15:C18) -> -4820990 | D19: =SUM(D15:D18) -> -6719107 | E19: =SUM(E15:E18) -> -5335342.7 | F19: =SUM(F15:F18) -> -5753570.1 | G19: =SUM(G15:G18) -> -5898666 | H19: =SUM(H15:H18) -> -6309463.6 | I19: =SUM(I15:I18) -> -6255992.9
A21: Financing activities
A22: Net change in deposits | B22: 11231904 | C22: 6954484 | D22: 11248505 | E22: =('Balance Sheet'!E20-'Balance Sheet'!D20)+('Balance Sheet'!E21-'Balance Sheet'!D21) -> 10468458 | F22: =('Balance Sheet'!F20-'Balance Sheet'!E20)+('Balance Sheet'!F21-'Balance Sheet'!E21) -> 11485394 | G22: =('Balance Sheet'!G20-'Balance Sheet'!F20)+('Balance Sheet'!G21-'Balance Sheet'!F21) -> 11868240 | H22: =('Balance Sheet'!H20-'Balance Sheet'!G20)+('Balance Sheet'!H21-'Balance Sheet'!G21) -> 12105605 | I22: =('Balance Sheet'!I20-'Balance Sheet'!H20)+('Balance Sheet'!I21-'Balance Sheet'!H21) -> 12497257
A23: Net change in debt and warehouse facilities | B23: -291213 | C23: -1497811 | D23: -1288928 | E23: =('Balance Sheet'!E25-'Balance Sheet'!D25)+('Balance Sheet'!E26-'Balance Sheet'!D26) -> -115162 | F23: =('Balance Sheet'!F25-'Balance Sheet'!E25)+('Balance Sheet'!F26-'Balance Sheet'!E26) -> -100000 | G23: =('Balance Sheet'!G25-'Balance Sheet'!F25)+('Balance Sheet'!G26-'Balance Sheet'!F26) -> -100000 | H23: =('Balance Sheet'!H25-'Balance Sheet'!G25)+('Balance Sheet'!H26-'Balance Sheet'!G26) -> -100000 | I23: =('Balance Sheet'!I25-'Balance Sheet'!H25)+('Balance Sheet'!I26-'Balance Sheet'!H26) -> -100000
A24: Proceeds from issuance of common stock, net | B24: 0 | C24: 0 | D24: 3182340 | E24: 0 | F24: 0 | G24: 0 | H24: 0 | I24: 0
A25: Other financing activities | B25: -55089 | C25: -422096 | D25: -32584 | E25: 0 | F25: 0 | G25: 0 | H25: 0 | I25: 0
A26: Net cash provided by financing activities | B26: =SUM(B22:B25) -> 10885602 | C26: =SUM(C22:C25) -> 5034577 | D26: =SUM(D22:D25) -> 13109333 | E26: =SUM(E22:E25) -> 10353296 | F26: =SUM(F22:F25) -> 11385394 | G26: =SUM(G22:G25) -> 11768240 | H26: =SUM(H22:H25) -> 12005605 | I26: =SUM(I22:I25) -> 12397257
A28: Effect of exchange rates on cash | B28: 677 | C28: 2 | D28: -355 | E28: 0 | F28: 0 | G28: 0 | H28: 0 | I28: 0
A29: Net change in cash, equivalents and restricted cash | B29: =B12+B19+B26+B28 -> 1769276 | C29: =C12+C19+C26+C28 -> -906218 | D29: =D12+D19+D26+D28 -> 2647413 | E29: =E12+E19+E26+E28 -> 1224212.3 | F29: =F12+F19+F26+F28 -> 1934326 | G29: =G12+G19+G26+G28 -> 2615165.2 | H29: =H12+H19+H26+H28 -> 2871152.8 | I29: =I12+I19+I26+I28 -> 3568013.7
A30: Cash, equivalents and restricted cash — beginning | B30: 1846302 | C30: 3615578 | D30: 2709360 | E30: =D33 -> 4929452 | F30: =E33 -> 6153664.3 | G30: =F33 -> 8087990.3 | H30: =G33 -> 10703156 | I30: =H33 -> 13574308
A31: Cash, equivalents and restricted cash — ending | B31: =B30+B29 -> 3615578 | C31: =C30+C29 -> 2709360 | D31: =D30+D29 -> 5356773 | E31: =E30+E29 -> 6153664.3 | F31: =F30+F29 -> 8087990.3 | G31: =G30+G29 -> 10703156 | H31: =H30+H29 -> 13574308 | I31: =I30+I29 -> 17142322
A32: Less: restricted cash | B32: ='Balance Sheet'!B6 -> 530558 | C32: ='Balance Sheet'!C6 -> 171067 | D32: ='Balance Sheet'!D6 -> 427321 | E32: 0 | F32: 0 | G32: 0 | H32: 0 | I32: 0
A33: Cash and cash equivalents per balance sheet | B33: =B31-B32 -> 3085020 | C33: =C31-C32 -> 2538293 | D33: =D31-D32 -> 4929452 | E33: =E31-E32 -> 6153664.3 | F33: =F31-F32 -> 8087990.3 | G33: =G31-G32 -> 10703156 | H33: =H31-H32 -> 13574308 | I33: =I31-I32 -> 17142322 | K33: Links to cash on the balance sheet; forecast holds restricted cash flat on the balance sheet

Sheet Budget vs Actual
A1: SoFi Technologies, Inc. — Budget vs Actual Variance
A2: FY2025 actual vs FY2025 budget (USD in thousands, except per-share) · Budget seeded from company guidance where published; all budget cells editable
A4: Variance flag threshold (|variance %| above this is flagged) | B4: 0.1
A6: Metric | B6: FY2025 Budget | C6: Budget source | D6: Override budget | E6: Effective budget | F6: FY2025 Actual | G6: Variance $ | H6: Variance % | I6: Flag
A7: Total net revenue (GAAP) | B7: 3300000 | C7: Placeholder — replace with your budget | E7: =IF(D7="",B7,D7) -> 3300000 | F7: ='Income Statement'!D15 -> 3613354 | G7: =F7-E7 -> 313354 | H7: =IF(E7=0,"",G7/E7) -> 0.094955758 | I7: =IF(H7="","",IF(ABS(H7)>$B$4,"⚠ REVIEW","OK")) -> OK
A8: Adjusted net revenue | B8: 3237500 | C8: Company FY25 guidance (Jan 27, 2025): $3,200–3,275M | E8: =IF(D8="",B8,D8) -> 3237500 | F8: 3591411 | G8: =F8-E8 -> 353911 | H8: =IF(E8=0,"",G8/E8) -> 0.10931614 | I8: =IF(H8="","",IF(ABS(H8)>$B$4,"⚠ REVIEW","OK")) -> ⚠ REVIEW
A9: Net interest income | B9: 2050000 | C9: Placeholder — replace with your budget | E9: =IF(D9="",B9,D9) -> 2050000 | F9: ='Income Statement'!D7 -> 2218956 | G9: =F9-E9 -> 168956 | H9: =IF(E9=0,"",G9/E9) -> 0.082417561 | I9: =IF(H9="","",IF(ABS(H9)>$B$4,"⚠ REVIEW","OK")) -> OK
A10: Total noninterest expense | B10: 2950000 | C10: Placeholder — replace with your budget | E10: =IF(D10="",B10,D10) -> 2950000 | F10: ='Income Statement'!D24 -> 3057178 | G10: =F10-E10 -> 107178 | H10: =IF(E10=0,"",G10/E10) -> 0.036331525 | I10: =IF(H10="","",IF(ABS(H10)>$B$4,"⚠ REVIEW","OK")) -> OK
A11: Adjusted EBITDA | B11: 855000 | C11: Company FY25 guidance: $845–865M | E11: =IF(D11="",B11,D11) -> 855000 | F11: 1053898 | G11: =F11-E11 -> 198898 | H11: =IF(E11=0,"",G11/E11) -> 0.23262924 | I11: =IF(H11="","",IF(ABS(H11)>$B$4,"⚠ REVIEW","OK")) -> ⚠ REVIEW
A12: Net income (GAAP) | B12: 295000 | C12: Company FY25 guidance: $285–305M | E12: =IF(D12="",B12,D12) -> 295000 | F12: ='Income Statement'!D27 -> 481320 | G12: =F12-E12 -> 186320 | H12: =IF(E12=0,"",G12/E12) -> 0.63159322 | I12: =IF(H12="","",IF(ABS(H12)>$B$4,"⚠ REVIEW","OK")) -> ⚠ REVIEW
A13: Diluted EPS (GAAP, $) | B13: 0.26 | C13: Company FY25 guidance: $0.25–0.27 | E13: =IF(D13="",B13,D13) -> 0.26 | F13: 0.39 | G13: =F13-E13 -> 0.13 | H13: =IF(E13=0,"",G13/E13) -> 0.5 | I13: =IF(H13="","",IF(ABS(H13)>$B$4,"⚠ REVIEW","OK")) -> ⚠ REVIEW
A15: Notes:
A16: • Budget column is seeded with the midpoint of company guidance issued at the start of FY2025 where published (see Budget source).
A17: • Rows marked "Placeholder" carry illustrative budgets — overwrite them, or type your own number in the yellow Override column (it takes precedence).
A18: • GAAP actuals pull live from the statement tabs (green); non-GAAP actuals are per the company's Q4 FY2025 earnings release.
A19: • Rows turn red automatically when |Variance %| exceeds the threshold in B4.

Sheet Market Inputs
A1: SoFi Technologies, Inc. — Market Inputs
A2: Snapshot as of market close July 17, 2026 · All values are inputs (blue) — see REFRESH section to wire live updates
A4: Data as of: | B4: July 17, 2026 | C4: Last refreshed: | D4: 2026-07-20 (initial snapshot)
A6: INTEREST RATES
A7: Fed funds target (upper bound) | B7: 0.0375 | F7: Range 3.50%–3.75%; unchanged at June 17, 2026 FOMC
A8: SOFR | B8: 0.0364 | F8: NY Fed, latest print
A9: 3-month T-bill (CMT) | B9: 0.0384 | F9: Fed H.15, Jul 16, 2026
A10: 2-year Treasury | B10: 0.0418 | F10: Close Jul 17, 2026
A11: 10-year Treasury | B11: 0.0455 | F11: Close Jul 17, 2026
A12: 30-year Treasury | B12: 0.0506 | F12: Close Jul 17, 2026
A14: EQUITY MARKET DATA — PEER SET
B15: PLTR | C15: HUBS | D15: SOFI
A16: Share price ($) | B16: 132.38 | C16: 224.26 | D16: 17.28
A17: Market cap ($mm) | B17: 317400 | C17: 11490 | D17: 22170
A18: Enterprise value ($mm) | B18: 309500 | C18: 10040 | D18: 20520
A19: Trailing P/E (x) | B19: 148.8 | C19: 119.2 | D19: 38.8
A20: Forward P/E (x) | B20: 83.3 | C20: 16.4 | D20: 26.4
A21: EV / Revenue, TTM (x) | B21: 59.3 | C21: 3 | D21: 5.2
A22: TTM revenue ($mm) | B22: 5220 | C22: 3300 | D22: 3910
A24: IMPLIED VALUATION CROSS-CHECK (uses this model's forecast)
A25: Selected EV / Revenue multiple (x) | B25: =D21 -> 5.2 | F25: Defaults to this company's current multiple — flex it or use a peer's
A26: Model FY2026E revenue ($000s) | B26: ='Income Statement'!E15 -> 4722869.3
A27: Implied enterprise value ($mm) | B27: =B25*B26/1000 -> 24558.921
A28: Current enterprise value ($mm) | B28: =D18 -> 20520
A29: Implied premium / (discount) to current EV | B29: =B27/B28-1 -> 0.19682848
A31: Selected forward P/E multiple (x) | B31: =D20 -> 26.4 | F31: Defaults to this company's current multiple — flex it or use a peer's
A32: Model FY2026E net income ($000s) | B32: ='Income Statement'!E29 -> 610286.11
A33: Implied market capitalization ($mm) | B33: =B31*B32/1000 -> 16111.553
A34: Current market capitalization ($mm) | B34: =D17 -> 22170
A35: Implied premium / (discount) to current market cap | B35: =B33/B34-1 -> -0.27327229
A37: REFRESH — MAKE THIS TAB LIVE (one-time setup, ~2 minutes in Excel)
A38: 1. Excel ▸ Data ▸ Get Data (Power Query) ▸ From Other Sources ▸ From Web.
A39: 2. Treasury yields (CSV, no key needed): https://home.treasury.gov/resource-center/data-chart-center/interest-rates/daily-treasury-rates.csv/2026/all?type=daily_treasury_yield_curve&field_tdr_date_value=2026&page&_format=csv
A40: 3. Load the query to a new sheet; point the blue rate cells above at the latest row (e.g. =INDEX(...)).
A41: 4. Share prices (JSON): https://query1.finance.yahoo.com/v8/finance/chart/SOFI — Power Query ▸ From Web, drill to chart.result.meta.regularMarketPrice.
A42: 5. After setup, Data ▸ Refresh All re-pulls everything with one click.
A43: 6. Until then this tab is a dated snapshot (see B4) — or ask Claude to refresh the numbers any time.
A44: Sources for this snapshot: Fed H.15 (Jul 17, 2026), NY Fed SOFR, stockanalysis.com / S&P Global (Jul 17–19, 2026).

Sheet Competitor Benchmarking
A1: SoFi Technologies, Inc. — Competitor Benchmarking
A2: Company column pulls live from this model (FY2025 actuals; FY2026E is scenario-aware) · comps per latest reported fiscal year, valuations as of July 17–20, 2026 · industry benchmarks: Clouded Judgement SaaS medians (7/10/26) and US bank norms
A4: Metric | B4: SoFi (model) | C4: Nu Holdings (NU, FY2025) | D4: LendingClub (LC, FY2025) | E4: Peer median | F4: Industry benchmark | H4: What it means
A5: Latest FY revenue ($mm) | B5: ='Income Statement'!D15/1000 -> 3613.354 | C5: 16300 | D5: 999 | E5: =MEDIAN(B5:D5) -> 3613.354 | F5: — | H5: SoFi's $3.6B revenue base is ~4x LendingClub but a fraction of Nu's LatAm franchise.
A6: Revenue growth — FY2025 % | B6: ='Income Statement'!D15/'Income Statement'!C15-1 -> 0.35085775 | C6: 0.45 | D6: 0.27 | E6: =MEDIAN(B6:D6) -> 0.35085775 | F6: ~3–5% | H6: 35% growth is ~8x typical bank growth — between NU (45%) and LC (27%); the fee/platform mix shift is doing the work.
